Workbook

Sheet 持有情况
A2: あら、奇遇ね（红过牌） | K2: ほら、一緒に持と♪（蓝再动） | U2: 仕事のつもりで臨みなさい（学生会） | AE2: ほっとけないクラスメイト（朝助） | AO2: 実食！例のSSD（蓝13） | AW2: 道具属性 | AY2: いつか、きっと花開く（sr黄睡）
C3: 破数 | E3: 营业 | F3: 第一属性 | G3: 第二属性 | H3: 第三属性 | M3: 破数 | O3: 抓a卡 | P3: 第一属性 | Q3: 第二属性 | R3: 第三属性 | W3: 破数 | Y3: 训练 | Z3: 第一属性 | AA3: 第二属性 | AB3: 第三属性 | AG3: 破数 | AI3: 强化 | AJ3: 第一属性 | AK3: 第二属性 | AL3: 第三属性 | AQ3: 破数 | AS3: 训练 | AT3: 第一属性 | AU3: 第二属性 | AV3: 第三属性 | AW3: 39 | BA3: 破数 | BC3: 强化 | BD3: 第一属性 | BE3: 第二属性 | BF3: 第三属性
C4: 4 | E4: =IF(C4=-1,0,IF(C4<=3,词条!C16,词条!D16)) -> 7 | F4: =IF(C4=-1,0,INT(C6+D6*路线!B14+E4*路线!B30+E6)) -> 173 | G4: =IF(C4=-1,0,INT(C6+D6*路线!B17+E4*路线!B30+E6)) -> 167 | H4: =IF(C4=-1,0,INT(C6+D6*路线!B20+E4*路线!B30+E6)) -> 149 | M4: 4 | O4: =IF(M4=-1,0,IF(M4<=3,词条!C14,词条!D14)) -> 3 | P4: =IF(M4=-1,0,INT((M6/100)*路线!B11+N6*路线!B14+O4*路线!B23+O6)) -> 170 | Q4: =IF(M4=-1,0,INT((M6/100)*路线!B12+N6*路线!B17+O4*路线!B23+O6)) -> 145 | R4: =IF(M4=-1,0,INT((M6/100)*路线!B13+N6*路线!B20+O4*路线!B23+O6)) -> 91 | W4: 4 | Y4: =IF(W4=-1,0,IF(W4<=3,词条!F6,词条!G6)) -> 4 | Z4: =IF(W4=-1,0,IF(路线!C6="计算",INT(W6+X6*路线!B24+Y4*路线!B14+Y6+20),INT(W6+X6*路线!B24+Y4*路线!B14+Y6))) -> 160 | AA4: =IF(W4=-1,0,IF(路线!C6="计算",INT(W6+X6*路线!B24+Y4*路线!B17+Y6+20),INT(W6+X6*路线!B24+Y4*路线!B17+Y6))) -> 156 | AB4: =IF(W4=-1,0,IF(路线!C6="计算",INT(W6+X6*路线!B24+Y4*路线!B20+Y6+20),INT(W6+X6*路线!B24+Y4*路线!B20+Y6))) -> 144 | AG4: 4 | AI4: =IF(AG4=-1,0,IF(AG4<=3,词条!I9,词条!J9)) -> 3 | AJ4: =IF(AG4=-1,0,INT(AG6+AH6*路线!B31+AI4*(路线!B28+路线!B29)+AI6)) -> 87 | AK4: =IF(AG4=-1,0,INT(AG6+AH6*路线!B31+AI4*(路线!B28+路线!B29)+AI6)) -> 87 | AL4: =IF(AG4=-1,0,INT(AG6+AH6*路线!B31+AI4*(路线!B28+路线!B29)+AI6)) -> 87 | AQ4: 4 | AS4: =IF(AQ4=-1,0,IF(AQ4<=3,词条!I6,词条!J6)) -> 4 | AT4: =IF(AQ4=-1,0,INT(AQ6+AR6*路线!B33+AS4*路线!B14+AS6)) -> 123 | AU4: =IF(AQ4=-1,0,INT(AQ6+AR6*路线!B33+AS4*路线!B17+AS6)) -> 119 | AV4: =IF(AQ4=-1,0,INT(AQ6+AR6*路线!B33+AS4*路线!B20+AS6)) -> 107 | AW4: =AT4+AW3 -> 162 | BA4: 4 | BC4: =IF(BA4=-1,0,IF(BA4<=3,词条!I9,词条!J9)) -> 3 | BD4: =IF(BA4=-1,0,INT(BA6+BB6*路线!B32+BC4*(路线!B28+路线!B29)+BC6)) -> 121 | BE4: =IF(BA4=-1,0,INT(BA6+BB6*路线!B32+BC4*(路线!B28+路线!B29)+BC6)) -> 121 | BF4: =IF(BA4=-1,0,INT(BA6+BB6*路线!B32+BC4*(路线!B28+路线!B29)+BC6)) -> 121
C5: 基础值 | D5: 训练 | E5: 事件 | M5: 百分比 | N5: 训练 | O5: 事件 | W5: 基础值 | X5: 抓m卡 | Y5: 事件 | AG5: 基础值 | AH5: 外出 | AI5: 事件 | AQ5: 基础值 | AR5: 相谈 | AS5: 事件 | AW5: =AU4+AW3 -> 158 | BA5: 基础值 | BB5: 休息 | BC5: 事件
C6: =IF(C4=-1,0,INDEX(词条!C3:G3,C4+1)) -> 60 | D6: =IF(C4=-1,0,IF(C4<=2,词条!C6,词条!D6)) -> 6 | E6: =IF(C4=-1,0,CHOOSE(C4+1,词条!C2,词条!D2,词条!D2,词条!D2,词条!E2)) -> 40 | F6: 通用 | M6: =IF(M4=-1,0,INDEX(词条!C4:G4,M4+1)) -> 8.5 | N6: =IF(M4=-1,0,IF(M4<=2,词条!C6,词条!D6)) -> 6 | O6: =IF(M4=-1,0,CHOOSE(M4+1,词条!C2,词条!D2,词条!D2,词条!D2,词条!E2)) -> 40 | P6: 通用 | W6: =IF(W4=-1,0,INDEX(词条!C3:G3,W4+1)) -> 60 | X6: =IF(W4=-1,0,IF(W4<=2,词条!F13,词条!G13)) -> 2 | Y6: =IF(W4=-1,0,CHOOSE(W4+1,词条!C2,词条!D2,词条!D2,词条!D2,词条!E2)) -> 40 | Z6: 通用 | AG6: =IF(AG4=-1,0,INDEX(词条!I3:M3,AG4+1)) -> 45 | AH6: =IF(AG4=-1,0,IF(AG4<=2,词条!I17,词条!J17)) -> 10 | AI6: =IF(AG4=-1,0,CHOOSE(AG4+1,词条!I2,词条!I2,词条!J2,词条!J2,词条!K2)) -> 30 | AJ6: 通用 | AQ6: =IF(AQ4=-1,0,INDEX(词条!I3:M3,AQ4+1)) -> 45 | AR6: =IF(AQ4=-1,0,IF(AQ4<=2,词条!I18,词条!J18)) -> 8 | AS6: =IF(AQ4=-1,0,CHOOSE(AQ4+1,词条!I2,词条!I2,词条!J2,词条!J2,词条!K2)) -> 30 | AT6: 通用 | AW6: =AV4 -> 107 | BA6: =IF(BA4=-1,0,INDEX(词条!I3:M3,BA4+1)) -> 45 | BB6: =IF(BA4=-1,0,IF(BA4<=2,词条!I5,词条!J5)) -> 17 | BC6: =IF(BA4=-1,0,CHOOSE(BA4+1,词条!I2,词条!I2,词条!J2,词条!J2,词条!K2)) -> 30 | BD6: 通用
A8: また、あんなに無理をして（红毛巾） | K8: まじか。（光舞台） | U8: 私の目に狂いはない（黄再动） | AE8: マイペース、マイライフ（红13） | AM8: 道具属性 | AO8: 嬉し恥ずかし夢心地（姐姐百科） | AW8: 道具属性 | AY8: 思惑とガクガク（黄13） | BG8: 道具属性
C9: 破数 | E9: 抓m卡 | F9: 第一属性 | G9: 第二属性 | H9: 第三属性 | M9: 破数 | O9: 相谈 | P9: 第一属性 | Q9: 第二属性 | R9: 第三属性 | W9: 破数 | Y9: 强化 | Z9: 第一属性 | AA9: 第二属性 | AB9: 第三属性 | AG9: 破数 | AI9: 训练 | AJ9: 第一属性 | AK9: 第二属性 | AL9: 第三属性 | AM9: 39 | AQ9: 破数 | AS9: 通常训练 | AT9: 第一属性 | AU9: 第二属性 | AV9: 第三属性 | AW9: 52 | BA9: 破数 | BC9: 训练 | BD9: 第一属性 | BE9: 第二属性 | BF9: 第三属性 | BG9: 39
C10: 4 | E10: =IF(C10=-1,0,IF(C10<=3,词条!C13,词条!D13)) -> 3 | F10: =IF(C10=-1,0,INT((C12/100)*路线!B11+D12*路线!B31+E10*路线!B24+E12)) -> 152 | G10: =IF(C10=-1,0,INT((C12/100)*路线!B12+D12*路线!B31+E10*路线!B24+E12)) -> 133 | H10: =IF(C10=-1,0,INT((C12/100)*路线!B13+D12*路线!B31+E10*路线!B24+E12)) -> 97 | M10: 4 | O10: =IF(M10=-1,0,IF(M10<=3,词条!C18,词条!D18)) -> 11 | P10: =IF(M10=-1,0,IF(路线!C6="计算",INT(M12+N12*路线!B14+O10*路线!B33+O12+20),INT(M12+N12*路线!B14+O10*路线!B33+O12))) -> 188 | Q10: =IF(M10=-1,0,IF(路线!C6="计算",INT(M12+N12*路线!B17+O10*路线!B33+O12+20),INT(M12+N12*路线!B17+O10*路线!B33+O12))) -> 182 | R10: =IF(M10=-1,0,IF(路线!C6="计算",INT(M12+N12*路线!B20+O10*路线!B33+O12+20),INT(M12+N12*路线!B20+O10*路线!B33+O12))) -> 164 | W10: 4 | Y10: =IF(W10=-1,0,IF(W10<=3,词条!C9,词条!D9)) -> 4 | Z10: =IF(W10=-1,0,INT((W12/100)*路线!B11+X12*路线!B30+Y10*(路线!B28+路线!B29)+Y12)) -> 181 | AA10: =IF(W10=-1,0,INT((W12/100)*路线!B12+X12*路线!B30+Y10*(路线!B28+路线!B29)+Y12)) -> 162 | AB10: =IF(W10=-1,0,INT((W12/100)*路线!B13+X12*路线!B30+Y10*(路线!B28+路线!B29)+Y12)) -> 126 | AG10: 4 | AI10: =IF(AG10=-1,0,IF(AG10<=3,词条!I6,词条!J6)) -> 4 | AJ10: =IF(AG10=-1,0,INT(AG12+AH12*路线!B33+AI10*路线!B14+AI12)) -> 123 | AK10: =IF(AG10=-1,0,INT(AG12+AH12*路线!B33+AI10*路线!B17+AI12)) -> 119 | AL10: =IF(AG10=-1,0,INT(AG12+AH12*路线!B33+AI10*路线!B20+AI12)) -> 107 | AM10: =AJ10+AM9 -> 162 | AQ10: 4 | AS10: =IF(AQ10=-1,0,IF(AQ10<=3,词条!I8,词条!J8)) -> 13 | AT10: =IF(AQ10=-1,0,INT(AQ12+AR12*路线!B30+AS10*路线!B16+AS12)) -> 110 | AU10: =IF(AQ10=-1,0,INT(AQ12+AR12*路线!B30+AS10*路线!B19+AS12)) -> 110 | AV10: =IF(AQ10=-1,0,INT(AQ12+AR12*路线!B30+AS10*路线!B22+AS12)) -> 110 | AW10: =AT10+AW9 -> 162 | BA10: 4 | BC10: =IF(BA10=-1,0,IF(BA10<=3,词条!I6,词条!J6)) -> 4 | BD10: =IF(BA10=-1,0,INT(BA12+BB12*路线!B33+BC10*路线!B14+BC12)) -> 123 | BE10: =IF(BA10=-1,0,INT(BA12+BB12*路线!B33+BC10*路线!B17+BC12)) -> 119 | BF10: =IF(BA10=-1,0,INT(BA12+BB12*路线!B33+BC10*路线!B20+BC12)) -> 107 | BG10: =BD10+BG9 -> 162
C11: 百分比 | D11: 外出 | E11: 事件 | M11: 基础值 | N11: 训练 | O11: 事件 | W11: 百分比 | X11: 营业 | Y11: 事件 | AG11: 基础值 | AH11: 相谈 | AI11: 事件 | AM11: =AK10+AM9 -> 158 | AQ11: 基础值 | AR11: 营业 | AS11: 事件 | AW11: =AU10+AW9 -> 162 | BA11: 基础值 | BB11: 相谈 | BC11: 事件 | BG11: =BE10+BG9 -> 158
C12: =IF(C10=-1,0,INDEX(词条!C4:G4,C10+1)) -> 8.5 | D12: =IF(C10=-1,0,IF(C10<=2,词条!C17,词条!D17)) -> 15 | E12: =IF(C10=-1,0,CHOOSE(C10+1,词条!C2,词条!D2,词条!D2,词条!D2,词条!E2)) -> 40 | F12: 通用 | M12: =IF(M10=-1,0,INDEX(词条!C3:G3,M10+1)) -> 60 | N12: =IF(M10=-1,0,IF(M10<=2,词条!C6,词条!D6)) -> 6 | O12: =IF(M10=-1,0,CHOOSE(M10+1,词条!C2,词条!D2,词条!D2,词条!D2,词条!E2)) -> 40 | P12: 通用 | W12: =IF(W10=-1,0,INDEX(词条!C4:G4,W10+1)) -> 8.5 | X12: =IF(W10=-1,0,IF(W10<=2,词条!C16,词条!D16)) -> 7 | Y12: =IF(W10=-1,0,CHOOSE(W10+1,词条!C2,词条!D2,词条!D2,词条!D2,词条!E2)) -> 40 | Z12: 通用 | AG12: =IF(AG10=-1,0,INDEX(词条!I3:M3,AG10+1)) -> 45 | AH12: =IF(AG10=-1,0,IF(AG10<=2,词条!I18,词条!J18)) -> 8 | AI12: =IF(AG10=-1,0,CHOOSE(AG10+1,词条!I2,词条!I2,词条!J2,词条!J2,词条!K2)) -> 30 | AJ12: 通用 | AM12: =AL10 -> 107 | AQ12: =IF(AQ10=-1,0,INDEX(词条!I3:M3,AQ10+1)) -> 45 | AR12: =IF(AQ10=-1,0,IF(AQ10<=2,词条!I16,词条!J16)) -> 5 | AS12: =IF(AQ10=-1,0,CHOOSE(AQ10+1,词条!I2,词条!I2,词条!J2,词条!J2,词条!K2)) -> 30 | AT12: 通用 | AW12: =AV10+AW9 -> 162 | BA12: =IF(BA10=-1,0,INDEX(词条!I3:M3,BA10+1)) -> 45 | BB12: =IF(BA10=-1,0,IF(BA10<=2,词条!I18,词条!J18)) -> 8 | BC12: =IF(BA10=-1,0,CHOOSE(BA10+1,词条!I2,词条!I2,词条!J2,词条!J2,词条!K2)) -> 30 | BD12: 通用 | BG12: =BF10 -> 107
A14: 可愛いと可愛いで可愛い！（三可爱） | K14: わたしたち、やればできる（蓝厨房） | U14: まるで王子様みたいな（王子） | AE14: 愛無き暗記は難しい（永年） | AM14: 道具属性 | AO14: ふわふわでワクワク（蓝饮料） | AY14: ほっぺた、ぷに（黄永年） | BG14: 道具属性
C15: 破数 | E15: 抓a卡 | F15: 第一属性 | G15: 第二属性 | H15: 第三属性 | M15: 破数 | O15: sp训练 | P15: 第一属性 | Q15: 第二属性 | R15: 第三属性 | W15: 破数 | Y15: 抓m卡 | Z15: 第一属性 | AA15: 第二属性 | AB15: 第三属性 | AG15: 破数 | AI15: 通常训练 | AJ15: 第一属性 | AK15: 第二属性 | AL15: 第三属性 | AM15: 52 | AQ15: 破数 | AS15: sp训练 | AT15: 第一属性 | AU15: 第二属性 | AV15: 第三属性 | BA15: 破数 | BC15: 通常训练 | BD15: 第一属性 | BE15: 第二属性 | BF15: 第三属性 | BG15: 52
C16: 4 | E16: =IF(C16=-1,0,IF(C16<=3,词条!C14,词条!D14)) -> 3 | F16: =IF(C16=-1,0,IF(路线!C6="计算",INT(C18+D18*路线!B15+E16*路线!B23+E18+20),INT(C18+D18*路线!B15+E16*路线!B23+E18))) -> 218 | G16: =IF(C16=-1,0,IF(路线!C6="计算",INT(C18+D18*路线!B18+E16*路线!B23+E18+20),INT(C18+D18*路线!B18+E16*路线!B23+E18))) -> 201 | H16: =IF(C16=-1,0,IF(路线!C6="计算",INT(C18+D18*路线!B21+E16*路线!B23+E18+20),INT(C18+D18*路线!B21+E16*路线!B23+E18))) -> 150 | M16: 4 | O16: =IF(M16=-1,0,IF(M16<=3,词条!F7,词条!G7)) -> 13 | P16: =IF(M16=-1,0,IF(路线!C6="计算",INT((M18/100)*路线!B11+N18*路线!B29+O16*路线!B15+O18+20),INT((M18/100)*路线!B11+N18*路线!B29+O16*路线!B15+O18))) -> 202 | Q16: =IF(M16=-1,0,IF(路线!C6="计算",INT((M18/100)*路线!B12+N18*路线!B29+O16*路线!B18+O18+20),INT((M18/100)*路线!B12+N18*路线!B29+O16*路线!B18+O18))) -> 170 | R16: =IF(M16=-1,0,IF(路线!C6="计算",INT((M18/100)*路线!B13+N18*路线!B29+O16*路线!B21+O18+20),INT((M18/100)*路线!B13+N18*路线!B29+O16*路线!B21+O18))) -> 95 | W16: 4 | Y16: =IF(W16=-1,0,IF(W16<=3,词条!C13,词条!D13)) -> 3 | Z16: =IF(W16=-1,0,INT(W18+X18*路线!B15+Y16*路线!B24+Y18)) -> 204 | AA16: =IF(W16=-1,0,INT(W18+X18*路线!B18+Y16*路线!B24+Y18)) -> 187 | AB16: =IF(W16=-1,0,INT(W18+X18*路线!B21+Y16*路线!B24+Y18)) -> 136 | AG16: 4 | AI16: =IF(AG16=-1,0,IF(AG16<=3,词条!I8,词条!J8)) -> 13 | AJ16: =IF(AG16=-1,0,INT(AG18+AH18*路线!B30+AI16*路线!B16+AI18)) -> 110 | AK16: =IF(AG16=-1,0,INT(AG18+AH18*路线!B30+AI16*路线!B19+AI18)) -> 110 | AL16: =IF(AG16=-1,0,INT(AG18+AH18*路线!B30+AI16*路线!B22+AI18)) -> 110 | AM16: =AJ16+AM15 -> 162 | AQ16: 4 | AS16: =IF(AQ16=-1,0,IF(AQ16<=3,词条!I7,词条!J7)) -> 13 | AT16: =IF(AQ16=-1,0,INT((AQ18/100)*路线!B11+AR18+AS16*路线!B15+AS18)) -> 156 | AU16: =IF(AQ16=-1,0,INT((AQ18/100)*路线!B12+AR18+AS16*路线!B18+AS18)) -> 129 | AV16: =IF(AQ16=-1,0,INT((AQ18/100)*路线!B13+AR18+AS16*路线!B21+AS18)) -> 63 | BA16: 4 | BC16: =IF(BA16=-1,0,IF(BA16<=3,词条!I8,词条!J8)) -> 13 | BD16: =IF(BA16=-1,0,INT((BA18/100)*路线!B11+BB18*路线!B30+BC16*路线!B16+BC18)) -> 122 | BE16: =IF(BA16=-1,0,INT((BA18/100)*路线!B12+BB18*路线!B30+BC16*路线!B19+BC18)) -> 108 | BF16: =IF(BA16=-1,0,INT((BA18/100)*路线!B13+BB18*路线!B30+BC16*路线!B22+BC18)) -> 81 | BG16: =BD16+BG15 -> 174
C17: 基础值 | D17: sp训练 | E17: 事件 | F17: SP | M17: 百分比 | N17: m强化 | O17: 事件 | W17: 基础值 | X17: sp训练 | Y17: 事件 | Z17: SP | AG17: 基础值 | AH17: 营业 | AI17: 事件 | AM17: =AK16+AM15 -> 162 | AQ17: 百分比 | AR17: 试验终了 | AS17: 事件 | AT17: SP | BA17: 百分比 | BB17: 营业 | BC17: 事件 | BG17: =BE16+BG15 -> 160
C18: =IF(C16=-1,0,INDEX(词条!C3:G3,C16+1)) -> 60 | D18: =IF(C16=-1,0,IF(C16<=2,词条!C7,词条!D7)) -> 17 | E18: =IF(C16=-1,0,CHOOSE(C16+1,词条!C2,词条!D2,词条!D2,词条!D2,词条!E2)) -> 40 | F18: 通用 | M18: =IF(M16=-1,0,INDEX(词条!C4:G4,M16+1)) -> 8.5 | N18: =IF(M16=-1,0,IF(M16<=2,词条!F10,词条!G10)) -> 7 | O18: =IF(M16=-1,0,CHOOSE(M16+1,词条!C2,词条!D2,词条!D2,词条!D2,词条!E2)) -> 40 | P18: 理性 | W18: =IF(W16=-1,0,INDEX(词条!C3:G3,W16+1)) -> 60 | X18: =IF(W16=-1,0,IF(W16<=2,词条!C7,词条!D7)) -> 17 | Y18: =IF(W16=-1,0,CHOOSE(W16+1,词条!C2,词条!D2,词条!D2,词条!D2,词条!E2)) -> 40 | Z18: 通用 | AG18: =IF(AG16=-1,0,INDEX(词条!I3:M3,AG16+1)) -> 45 | AH18: =IF(AG16=-1,0,IF(AG16<=2,词条!I16,词条!J16)) -> 5 | AI18: =IF(AG16=-1,0,CHOOSE(AG16+1,词条!I2,词条!I2,词条!J2,词条!J2,词条!K2)) -> 30 | AJ18: 通用 | AM18: =AL16+AM15 -> 162 | AQ18: =IF(AQ16=-1,0,INDEX(词条!I4:M4,AQ16+1)) -> 6.4 | AR18: =IF(AQ16=-1,0,IF(AQ16<=2,词条!I19,词条!J19)) -> 17 | AS18: =IF(AQ16=-1,0,CHOOSE(AQ16+1,词条!I2,词条!I2,词条!J2,词条!J2,词条!K2)) -> 30 | AT18: 通用 | BA18: =IF(BA16=-1,0,INDEX(词条!I4:M4,BA16+1)) -> 6.4 | BB18: =IF(BA16=-1,0,IF(BA16<=2,词条!I16,词条!J16)) -> 5 | BC18: =IF(BA16=-1,0,CHOOSE(BA16+1,词条!I2,词条!I2,词条!J2,词条!J2,词条!K2)) -> 30 | BD18: 通用 | BG18: =BF16+BG15 -> 133
A20: 次の桜の季節には。（花荫） | K20: おいしい顔、いただき～！（蓝拍照） | U20: お疲れ様、千奈ちゃん。（辛苦了千奈） | AE20: のらりくらりしっかり | AO20: 魅惑の大腿四頭筋 | AY20: てとりあしとり
C21: 破数 | E21: 强化 | F21: 第一属性 | G21: 第二属性 | H21: 第三属性 | M21: 破数 | O21: 强化 | P21: 第一属性 | Q21: 第二属性 | R21: 第三属性 | W21: 破数 | Y21: 抓a卡 | Z21: 第一属性 | AA21: 第二属性 | AB21: 第三属性 | AG21: 破数 | AI21: 训练 | AJ21: 第一属性 | AK21: 第二属性 | AL21: 第三属性 | AQ21: 破数 | AS21: 训练 | AT21: 第一属性 | AU21: 第二属性 | AV21: 第三属性 | BA21: 破数 | BC21: 训练 | BD21: 第一属性 | BE21: 第二属性 | BF21: 第三属性
C22: 4 | E22: =IF(C22=-1,0,IF(C22<=3,词条!C9,词条!D9)) -> 4 | F22: =IF(C22=-1,0,IF(路线!C6="计算",INT((C24/100)*路线!B11+D24*路线!B14+E22*(路线!B28+路线!B29)+E24+20),INT((C24/100)*路线!B11+D24*路线!B14+E22*(路线!B28+路线!B29)+E24))) -> 176 | G22: =IF(C22=-1,0,IF(路线!C6="计算",INT((C24/100)*路线!B12+D24*路线!B17+E22*(路线!B28+路线!B29)+E24+20),INT((C24/100)*路线!B12+D24*路线!B17+E22*(路线!B28+路线!B29)+E24))) -> 151 | H22: =IF(C22=-1,0,IF(路线!C6="计算",INT((C24/100)*路线!B13+D24*路线!B20+E22*(路线!B28+路线!B29)+E24+20),INT((C24/100)*路线!B13+D24*路线!B20+E22*(路线!B28+路线!B29)+E24))) -> 97 | M22: 4 | O22: =IF(M22=-1,0,IF(M22<=3,词条!C9,词条!D9)) -> 4 | P22: =IF(M22=-1,0,IF(路线!C6="计算",INT(M24+N24*路线!B15+O22*(路线!B28+路线!B29)+O24+20),INT(M24+N24*路线!B15+O22*(路线!B28+路线!B29)+O24))) -> 204 | Q22: =IF(M22=-1,0,IF(路线!C6="计算",INT(M24+N24*路线!B18+O22*(路线!B28+路线!B29)+O24+20),INT(M24+N24*路线!B18+O22*(路线!B28+路线!B29)+O24))) -> 187 | R22: =IF(M22=-1,0,IF(路线!C6="计算",INT(M24+N24*路线!B21+O22*(路线!B28+路线!B29)+O24+20),INT(M24+N24*路线!B21+O22*(路线!B28+路线!B29)+O24))) -> 136 | W22: 4 | Y22: =IF(W22=-1,0,IF(W22<=3,词条!C14,词条!D14)) -> 3 | Z22: =IF(W22=-1,0,IF(路线!C6="计算",INT((W24/100)*路线!B11+X24*路线!B14+Y22*路线!B23+Y24+20),INT((W24/100)*路线!B11+X24*路线!B14+Y22*路线!B23+Y24))) -> 190 | AA22: =IF(W22=-1,0,IF(路线!C6="计算",INT((W24/100)*路线!B12+X24*路线!B17+Y22*路线!B23+Y24+20),INT((W24/100)*路线!B12+X24*路线!B17+Y22*路线!B23+Y24))) -> 165 | AB22: =IF(W22=-1,0,IF(路线!C6="计算",INT((W24/100)*路线!B13+X24*路线!B20+Y22*路线!B23+Y24+20),INT((W24/100)*路线!B13+X24*路线!B20+Y22*路线!B23+Y24))) -> 111 | AG22: 4 | AI22: =IF(AG22=-1,0,IF(AG22<=3,词条!I6,词条!J6)) -> 4 | AJ22: =IF(AG22=-1,0,IF(路线!C6="计算",INT((AG24/100)*路线!B11+AH24*路线!B34+AI22*路线!B14+AI24+20),INT((AG24/100)*路线!B11+AH24*路线!B34+AI22*路线!B14+AI24))) -> 156 | AK22: =IF(AG22=-1,0,IF(路线!C6="计算",INT((AG24/100)*路线!B12+AH24*路线!B34+AI22*路线!B17+AI24+20),INT((AG24/100)*路线!B12+AH24*路线!B34+AI22*路线!B17+AI24))) -> 138 | AL22: =IF(AG22=-1,0,IF(路线!C6="计算",INT((AG24/100)*路线!B13+AH24*路线!B34+AI22*路线!B20+AI24+20),INT((AG24/100)*路线!B13+AH24*路线!B34+AI22*路线!B20+AI24))) -> 99 | AQ22: 4 | AS22: =IF(AQ22=-1,0,IF(AQ22<=3,词条!I6,词条!J6)) -> 4 | AT22: =IF(AQ22=-1,0,IF(路线!C6="计算",INT((AQ24/100)*路线!B11+AR24*路线!B34+AS22*路线!B14+AS24+20),INT((AQ24/100)*路线!B11+AR24*路线!B34+AS22*路线!B14+AS24))) -> 156 | AU22: =IF(AQ22=-1,0,IF(路线!C6="计算",INT((AQ24/100)*路线!B12+AR24*路线!B34+AS22*路线!B17+AS24+20),INT((AQ24/100)*路线!B12+AR24*路线!B34+AS22*路线!B17+AS24))) -> 138 | AV22: =IF(AQ22=-1,0,IF(路线!C6="计算",INT((AQ24/100)*路线!B13+AR24*路线!B34+AS22*路线!B20+AS24+20),INT((AQ24/100)*路线!B13+AR24*路线!B34+AS22*路线!B20+AS24))) -> 99 | BA22: 4 | BC22: =IF(BA22=-1,0,IF(BA22<=3,词条!I6,词条!J6)) -> 4 | BD22: =IF(BA22=-1,0,IF(路线!C6="计算",INT(BA24+BB24*路线!B34+BC22*路线!B14+BC24+20),INT(BA24+BB24*路线!B34+BC22*路线!B14+BC24))) -> 144 | BE22: =IF(BA22=-1,0,IF(路线!C6="计算",INT(BA24+BB24*路线!B34+BC22*路线!B17+BC24+20),INT(BA24+BB24*路线!B34+BC22*路线!B17+BC24))) -> 140 | BF22: =IF(BA22=-1,0,IF(路线!C6="计算",INT(BA24+BB24*路线!B34+BC22*路线!B20+BC24+20),INT(BA24+BB24*路线!B34+BC22*路线!B20+BC24))) -> 128
C23: 百分比 | D23: 训练 | E23: 事件 | M23: 基础值 | N23: sp训练 | O23: 事件 | P23: SP | W23: 百分比 | X23: 训练 | Y23: 事件 | AG23: 百分比 | AH23: 支给 | AI23: 事件 | AQ23: 百分比 | AR23: 支给 | AS23: 事件 | BA23: 基础值 | BB23: 支给 | BC23: 事件
C24: =IF(C22=-1,0,INDEX(词条!C4:G4,C22+1)) -> 8.5 | D24: =IF(C22=-1,0,IF(C22<=2,词条!C6,词条!D6)) -> 6 | E24: =IF(C22=-1,0,CHOOSE(C22+1,词条!C2,词条!D2,词条!D2,词条!D2,词条!E2)) -> 40 | F24: 通用 | M24: =IF(M22=-1,0,INDEX(词条!C3:G3,M22+1)) -> 60 | N24: =IF(M22=-1,0,IF(M22<=2,词条!C7,词条!D7)) -> 17 | O24: =IF(M22=-1,0,CHOOSE(M22+1,词条!C2,词条!D2,词条!D2,词条!D2,词条!E2)) -> 40 | P24: 通用 | W24: =IF(W22=-1,0,INDEX(词条!C4:G4,W22+1)) -> 8.5 | X24: =IF(W22=-1,0,IF(W22<=2,词条!C6,词条!D6)) -> 6 | Y24: =IF(W22=-1,0,CHOOSE(W22+1,词条!C2,词条!D2,词条!D2,词条!D2,词条!E2)) -> 40 | Z24: 通用 | AG24: =IF(AG22=-1,0,INDEX(词条!I4:M4,AG22+1)) -> 6.4 | AH24: =IF(AG22=-1,0,IF(AG22<=2,词条!I12,词条!J12)) -> 11 | AI24: =IF(AG22=-1,0,CHOOSE(AG22+1,词条!I2,词条!I2,词条!J2,词条!J2,词条!K2)) -> 30 | AJ24: 通用 | AQ24: =IF(AQ22=-1,0,INDEX(词条!I4:M4,AQ22+1)) -> 6.4 | AR24: =IF(AQ22=-1,0,IF(AQ22<=2,词条!I12,词条!J12)) -> 11 | AS24: =IF(AQ22=-1,0,CHOOSE(AQ22+1,词条!I2,词条!I2,词条!J2,词条!J2,词条!K2)) -> 30 | AT24: 通用 | BA24: =IF(BA22=-1,0,INDEX(词条!I3:M3,BA22+1)) -> 45 | BB24: =IF(BA22=-1,0,IF(BA22<=2,词条!I12,词条!J12)) -> 11 | BC24: =IF(BA22=-1,0,CHOOSE(BA22+1,词条!I2,词条!I2,词条!J2,词条!J2,词条!K2)) -> 30 | BD24: 通用
A26: こいつらめんどくさー（红吵架） | K26: ぐぬぬぬぬ…………！（蓝50） | U26: お姉ちゃんに任せなさい！（黄发卡） | AE26: 今はあえて、背を向けて（刺猬） | AO26: パシャっとキメポ（sr蓝睡） | AY26: 体当たりのラブコール（过肩摔）
C27: 破数 | E27: sp训练 | F27: 第一属性 | G27: 第二属性 | H27: 第三属性 | M27: 破数 | O27: 抓m卡 | P27: 第一属性 | Q27: 第二属性 | R27: 第三属性 | W27: 破数 | Y27: 强化 | Z27: 第一属性 | AA27: 第二属性 | AB27: 第三属性 | AG27: 破数 | AI27: sp训练 | AJ27: 第一属性 | AK27: 第二属性 | AL27: 第三属性 | AQ27: 破数 | AS27: 训练 | AT27: 第一属性 | AU27: 第二属性 | AV27: 第三属性 | BA27: 破数 | BC27: sp训练 | BD27: 第一属性 | BE27: 第二属性 | BF27: 第三属性
C28: 4 | E28: =IF(C28=-1,0,IF(C28<=3,词条!F7,词条!G7)) -> 13 | F28: =IF(C28=-1,0,IF(路线!C6="计算",INT((C30/100)*路线!B11+D30*路线!B29+E28*路线!B15+E30+20),INT((C30/100)*路线!B11+D30*路线!B29+E28*路线!B15+E30))) -> 202 | G28: =IF(C28=-1,0,IF(路线!C6="计算",INT((C30/100)*路线!B12+D30*路线!B29+E28*路线!B18+E30+20),INT((C30/100)*路线!B12+D30*路线!B29+E28*路线!B18+E30))) -> 170 | H28: =IF(C28=-1,0,IF(路线!C6="计算",INT((C30/100)*路线!B13+D30*路线!B29+E28*路线!B21+E30+20),INT((C30/100)*路线!B13+D30*路线!B29+E28*路线!B21+E30))) -> 95 | M28: 4 | O28: =IF(M28=-1,0,IF(M28<=3,词条!C13,词条!D13)) -> 3 | P28: =IF(M28=-1,0,INT((M30/100)*路线!B11+N30*路线!B34+O28*路线!B24+O30)) -> 203 | Q28: =IF(M28=-1,0,INT((M30/100)*路线!B12+N30*路线!B34+O28*路线!B24+O30)) -> 184 | R28: =IF(M28=-1,0,INT((M30/100)*路线!B13+N30*路线!B34+O28*路线!B24+O30)) -> 148 | W28: 4 | Y28: =IF(W28=-1,0,IF(W28<=3,词条!C9,词条!D9)) -> 4 | Z28: =IF(W28=-1,0,INT((W30/100)*路线!B11+X30*路线!B15+Y28*(路线!B28+路线!B29)+Y30)) -> 200 | AA28: =IF(W28=-1,0,INT((W30/100)*路线!B12+X30*路线!B18+Y28*(路线!B28+路线!B29)+Y30)) -> 164 | AB28: =IF(W28=-1,0,INT((W30/100)*路线!B13+X30*路线!B21+Y28*(路线!B28+路线!B29)+Y30)) -> 77 | AG28: 4 | AI28: =IF(AG28=-1,0,IF(AG28<=3,词条!I7,词条!J7)) -> 13 | AJ28: =IF(AG28=-1,0,INT((AG30/100)*路线!B11+AH30+AI28*路线!B15+AI30)) -> 156 | AK28: =IF(AG28=-1,0,INT((AG30/100)*路线!B12+AH30+AI28*路线!B18+AI30)) -> 129 | AL28: =IF(AG28=-1,0,INT((AG30/100)*路线!B13+AH30+AI28*路线!B21+AI30)) -> 63 | AQ28: 4 | AS28: =IF(AQ28=-1,0,IF(AQ28<=3,词条!I6,词条!J6)) -> 4 | AT28: =IF(AQ28=-1,0,IF(路线!C6="计算",INT(AQ30+AR30*路线!B32+AS28*路线!B14+AS30+20),INT(AQ30+AR30*路线!B32+AS28*路线!B14+AS30))) -> 145 | AU28: =IF(AQ28=-1,0,IF(路线!C6="计算",INT(AQ30+AR30*路线!B32+AS28*路线!B17+AS30+20),INT(AQ30+AR30*路线!B32+AS28*路线!B17+AS30))) -> 141 | AV28: =IF(AQ28=-1,0,IF(路线!C6="计算",INT(AQ30+AR30*路线!B32+AS28*路线!B20+AS30+20),INT(AQ30+AR30*路线!B32+AS28*路线!B20+AS30))) -> 129 | BA28: 4 | BC28: =IF(BA28=-1,0,IF(BA28<=3,词条!I7,词条!J7)) -> 13 | BD28: =IF(BA28=-1,0,IF(路线!C6="计算",INT((BA30/100)*路线!B11+BB30+BC28*路线!B15+BC30+20),INT((BA30/100)*路线!B11+BB30+BC28*路线!B15+BC30))) -> 176 | BE28: =IF(BA28=-1,0,IF(路线!C6="计算",INT((BA30/100)*路线!B12+BB30+BC28*路线!B18+BC30+20),INT((BA30/100)*路线!B12+BB30+BC28*路线!B18+BC30))) -> 149 | BF28: =IF(BA28=-1,0,IF(路线!C6="计算",INT((BA30/100)*路线!B13+BB30+BC28*路线!B21+BC30+20),INT((BA30/100)*路线!B13+BB30+BC28*路线!B21+BC30))) -> 83
C29: 百分比 | D29: m强化 | E29: 事件 | M29: 百分比 | N29: 支给 | O29: 事件 | W29: 百分比 | X29: sp训练 | Y29: 事件 | AG29: 百分比 | AH29: 试验终了 | AI29: 事件 | AJ29: SP | AQ29: 基础值 | AR29: 休息 | AS29: 事件 | BA29: 百分比 | BB29: 试验终了 | BC29: 事件 | BD29: SP
C30: =IF(C28=-1,0,INDEX(词条!C4:G4,C28+1)) -> 8.5 | D30: =IF(C28=-1,0,IF(C28<=2,词条!F10,词条!G10)) -> 7 | E30: =IF(C28=-1,0,CHOOSE(C28+1,词条!C2,词条!D2,词条!D2,词条!D2,词条!E2)) -> 40 | F30: 感性 | M30: =IF(M28=-1,0,INDEX(词条!C4:G4,M28+1)) -> 8.5 | N30: =IF(M28=-1,0,IF(M28<=2,词条!C12,词条!D12)) -> 17 | O30: =IF(M28=-1,0,CHOOSE(M28+1,词条!C2,词条!D2,词条!D2,词条!D2,词条!E2)) -> 40 | P30: 通用 | W30: =IF(W28=-1,0,INDEX(词条!C4:G4,W28+1)) -> 8.5 | X30: =IF(W28=-1,0,IF(W28<=2,词条!C7,词条!D7)) -> 17 | Y30: =IF(W28=-1,0,CHOOSE(W28+1,词条!C2,词条!D2,词条!D2,词条!D2,词条!E2)) -> 40 | Z30: 通用 | AG30: =IF(AG28=-1,0,INDEX(词条!I4:M4,AG28+1)) -> 6.4 | AH30: =IF(AG28=-1,0,IF(AG28<=2,词条!I19,词条!J19)) -> 17 | AI30: =IF(AG28=-1,0,CHOOSE(AG28+1,词条!I2,词条!I2,词条!J2,词条!J2,词条!K2)) -> 30 | AJ30: 通用 | AQ30: =IF(AQ28=-1,0,INDEX(词条!I3:M3,AQ28+1)) -> 45 | AR30: =IF(AQ28=-1,0,IF(AQ28<=2,词条!I5,词条!J5)) -> 17 | AS30: =IF(AQ28=-1,0,CHOOSE(AQ28+1,词条!I2,词条!I2,词条!J2,词条!J2,词条!K2)) -> 30 | AT30: 感性 | BA30: =IF(BA28=-1,0,INDEX(词条!I4:M4,BA28+1)) -> 6.4 | BB30: =IF(BA28=-1,0,IF(BA28<=2,词条!I19,词条!J19)) -> 17 | BC30: =IF(BA28=-1,0,CHOOSE(BA28+1,词条!I2,词条!I2,词条!J2,词条!J2,词条!K2)) -> 30 | BD30: 通用
A32: 何やってるんだろう、（红再动） | K32: 晴れたね（蓝睡） | U32: あなたにも作ってあげる！（黄睡） | AE32: イヤホンはんぶんこ | AO32: どりゃぎゃ（矿泉水） | AW32: 道具属性 | AX32: 好调抓卡 | AY32: かちこちストレッチ（菲柱体前屈） | BG32: 道具属性 | BH32: 好印象抓卡
C33: 破数 | E33: 强化 | F33: 第一属性 | G33: 第二属性 | H33: 第三属性 | M33: 破数 | O33: 外出 | P33: 第一属性 | Q33: 第二属性 | R33: 第三属性 | W33: 破数 | Y33: 休息 | Z33: 第一属性 | AA33: 第二属性 | AB33: 第三属性 | AG33: 破数 | AI33: 休息 | AJ33: 第一属性 | AK33: 第二属性 | AL33: 第三属性 | AQ33: 破数 | AS33: 训练 | AT33: 第一属性 | AU33: 第二属性 | AV33: 第三属性 | AW33: =AX33*6 -> 60 | AX33: 10 | BA33: 破数 | BC33: sp训练 | BD33: 第一属性 | BE33: 第二属性 | BF33: 第三属性 | BG33: =BH33*6 -> 60 | BH33: 10
C34: 4 | E34: =IF(C34=-1,0,IF(C34<=3,词条!C9,词条!D9)) -> 4 | F34: =IF(C34=-1,0,INT(C36+D36*路线!B14+E34*(路线!B28+路线!B29)+E36)) -> 140 | G34: =IF(C34=-1,0,INT(C36+D36*路线!B17+E34*(路线!B28+路线!B29)+E36)) -> 134 | H34: =IF(C34=-1,0,INT(C36+D36*路线!B20+E34*(路线!B28+路线!B29)+E36)) -> 116 | M34: 4 | O34: =IF(M34=-1,0,IF(M34<=3,词条!C17,词条!D17)) -> 15 | P34: =IF(M34=-1,0,INT((M36/100)*路线!B11+N36*路线!B32+O34*路线!B31+O36)) -> 160 | Q34: =IF(M34=-1,0,INT((M36/100)*路线!B12+N36*路线!B32+O34*路线!B31+O36)) -> 141 | R34: =IF(M34=-1,0,INT((M36/100)*路线!B13+N36*路线!B32+O34*路线!B31+O36)) -> 105 | W34: 4 | Y34: =IF(W34=-1,0,IF(W34<=3,词条!C5,词条!D5)) -> 22 | Z34: =IF(W34=-1,0,INT(W36+X36*路线!B14+Y34*路线!B32+Y36)) -> 168 | AA34: =IF(W34=-1,0,INT(W36+X36*路线!B17+Y34*路线!B32+Y36)) -> 162 | AB34: =IF(W34=-1,0,INT(W36+X36*路线!B20+Y34*路线!B32+Y36)) -> 144 | AG34: 4 | AI34: =IF(AG34=-1,0,IF(AG34<=3,词条!I5,词条!J5)) -> 17 | AJ34: =IF(AG34=-1,0,IF(路线!C6="计算",INT(AG36+AH36*路线!B31+AI34*路线!B32+AI36+20),INT(AG36+AH36*路线!B31+AI34*路线!B32+AI36))) -> 129 | AK34: =IF(AG34=-1,0,IF(路线!C6="计算",INT(AG36+AH36*路线!B31+AI34*路线!B32+AI36+20),INT(AG36+AH36*路线!B31+AI34*路线!B32+AI36))) -> 129 | AL34: =IF(AG34=-1,0,IF(路线!C6="计算",INT(AG36+AH36*路线!B31+AI34*路线!B32+AI36+20),INT(AG36+AH36*路线!B31+AI34*路线!B32+AI36))) -> 129 | AQ34: 4 | AS34: =IF(AQ34=-1,0,IF(AQ34<=3,词条!I6,词条!J6)) -> 4 | AT34: =IF(AQ34=-1,0,INT(AQ36+AR36*路线!B34+AS34*路线!B14+AS36)) -> 124 | AU34: =IF(AQ34=-1,0,INT(AQ36+AR36*路线!B34+AS34*路线!B17+AS36)) -> 120 | AV34: =IF(AQ34=-1,0,INT(AQ36+AR36*路线!B34+AS34*路线!B20+AS36)) -> 108 | AW34: =AT34+AW33 -> 184 | BA34: 4 | BC34: =IF(BA34=-1,0,IF(BA34<=3,词条!I7,词条!J7)) -> 13 | BD34: =IF(BA34=-1,0,INT((BA36/100)*路线!B11+BB36*路线!B33+BC34*路线!B15+BC36)) -> 171 | BE34: =IF(BA34=-1,0,INT((BA36/100)*路线!B12+BB36*路线!B33+BC34*路线!B18+BC36)) -> 144 | BF34: =IF(BA34=-1,0,INT((BA36/100)*路线!B13+BB36*路线!B33+BC34*路线!B21+BC36)) -> 78 | BG34: =BD34+BG33 -> 231
C35: 基础值 | D35: 训练 | E35: 事件 | F35: SP | M35: 百分比 | N35: 休息 | O35: 事件 | W35: 基础值 | X35: 训练 | Y35: 事件 | AG35: 基础值 | AH35: 外出 | AI35: 事件 | AQ35: 基础值 | AR35: 支给 | AS35: 事件 | AT35: SP | AW35: =AU34+AW33 -> 180 | BA35: 百分比 | BB35: 相谈 | BC35: 事件 | BG35: =BE34+BG33 -> 204
C36: =IF(C34=-1,0,INDEX(词条!C3:G3,C34+1)) -> 60 | D36: =IF(C34=-1,0,IF(C34<=2,词条!C6,词条!D6)) -> 6 | E36: =IF(C34=-1,0,CHOOSE(C34+1,词条!C2,词条!D2,词条!D2,词条!D2,词条!E2)) -> 40 | F36: 通用 | M36: =IF(M34=-1,0,INDEX(词条!C4:G4,M34+1)) -> 8.5 | N36: =IF(M34=-1,0,IF(M34<=2,词条!C5,词条!D5)) -> 22 | O36: =IF(M34=-1,0,CHOOSE(M34+1,词条!C2,词条!D2,词条!D2,词条!D2,词条!E2)) -> 40 | P36: 通用 | W36: =IF(W34=-1,0,INDEX(词条!C3:G3,W34+1)) -> 60 | X36: =IF(W34=-1,0,IF(W34<=2,词条!C6,词条!D6)) -> 6 | Y36: =IF(W34=-1,0,CHOOSE(W34+1,词条!C2,词条!D2,词条!D2,词条!D2,词条!E2)) -> 40 | Z36: 通用 | AG36: =IF(AG34=-1,0,INDEX(词条!I3:M3,AG34+1)) -> 45 | AH36: =IF(AG34=-1,0,IF(AG34<=2,词条!I17,词条!J17)) -> 10 | AI36: =IF(AG34=-1,0,CHOOSE(AG34+1,词条!I2,词条!I2,词条!J2,词条!J2,词条!K2)) -> 30 | AJ36: 理性 | AQ36: =IF(AQ34=-1,0,INDEX(词条!I3:M3,AQ34+1)) -> 45 | AR36: =IF(AQ34=-1,0,IF(AQ34<=2,词条!I12,词条!J12)) -> 11 | AS36: =IF(AQ34=-1,0,CHOOSE(AQ34+1,词条!I2,词条!I2,词条!J2,词条!J2,词条!K2)) -> 30 | AT36: 感性 | AW36: =AV34+AW33 -> 168 | BA36: =IF(BA34=-1,0,INDEX(词条!I4:M4,BA34+1)) -> 6.4 | BB36: =IF(BA34=-1,0,IF(BA34<=2,词条!I18,词条!J18)) -> 8 | BC36: =IF(BA34=-1,0,CHOOSE(BA34+1,词条!I2,词条!I2,词条!J2,词条!J2,词条!K2)) -> 30 | BD36: 理性 | BG36: =BF34+BG33 -> 138
A38: まだ上がりませんように！（撑伞） | K38: もうっ！ 冷たいよ！（蓝喷水） | U38: 第2回教室パーティー！（一年一班） | AE38: 海、楽しまなきゃ！（sr红睡） | AM38: 道具属性 | AN38: 干劲抓卡 | AO38: ふわふわなお面？（小熊） | AY38: やさしさ、あったかい（白毛哭哭）
C39: 破数 | E39: m强化 | F39: 第一属性 | G39: 第二属性 | H39: 第三属性 | M39: 破数 | O39: 试验终了 | P39: 第一属性 | Q39: 第二属性 | R39: 第三属性 | W39: 破数 | Y39: 试验终了 | Z39: 第一属性 | AA39: 第二属性 | AB39: 第三属性 | AG39: 破数 | AJ39: 第一属性 | AK39: 第二属性 | AL39: 第三属性 | AM39: =AN39*6 -> 60 | AN39: 10 | AQ39: 破数 | AS39: sp训练 | AT39: 第一属性 | AU39: 第二属性 | AV39: 第三属性 | BA39: 破数 | BC39: 训练 | BD39: 第一属性 | BE39: 第二属性 | BF39: 第三属性
C40: 4 | E40: =IF(C40=-1,0,IF(C40<=3,词条!C10,词条!D11)) -> 9 | F40: =IF(C40=-1,0,IF(路线!C6="计算",INT((C42/100)*路线!B11+D42*路线!B15+E40*路线!B29+E42+20),INT((C42/100)*路线!B11+D42*路线!B15+E40*路线!B29+E42))) -> 222 | G40: =IF(C40=-1,0,IF(路线!C6="计算",INT((C42/100)*路线!B12+D42*路线!B18+E40*路线!B29+E42+20),INT((C42/100)*路线!B12+D42*路线!B18+E40*路线!B29+E42))) -> 186 | H40: =IF(C40=-1,0,IF(路线!C6="计算",INT((C42/100)*路线!B13+D42*路线!B21+E40*路线!B29+E42+20),INT((C42/100)*路线!B13+D42*路线!B21+E40*路线!B29+E42))) -> 99 | M40: 4 | O40: =IF(M40=-1,0,IF(M40<=3,词条!C19,词条!D19)) -> 22 | P40: =IF(M40=-1,0,INT(M42+N42*路线!B15+O40+O42)) -> 190 | Q40: =IF(M40=-1,0,INT(M42+N42*路线!B18+O40+O42)) -> 173 | R40: =IF(M40=-1,0,INT(M42+N42*路线!B21+O40+O42)) -> 122 | W40: 4 | Y40: =IF(W40=-1,0,IF(W40<=3,词条!F19,词条!G19)) -> 17 | Z40: =IF(W40=-1,0,IF(路线!C6="计算",INT(W42+X42*路线!B14+Y40+Y42+20),INT(W42+X42*路线!B14+Y40+Y42))) -> 153 | AA40: =IF(W40=-1,0,IF(路线!C6="计算",INT(W42+X42*路线!B17+Y40+Y42+20),INT(W42+X42*路线!B17+Y40+Y42))) -> 149 | AB40: =IF(W40=-1,0,IF(路线!C6="计算",INT(W42+X42*路线!B20+Y40+Y42+20),INT(W42+X42*路线!B20+Y40+Y42))) -> 137 | AG40: 4 | AJ40: =IF(AG40=-1,0,INT(AG42+AH42*路线!B32+AI42)) -> 109 | AK40: =IF(AG40=-1,0,INT(AG42+AH42*路线!B32+AI42)) -> 109 | AL40: =IF(AG40=-1,0,INT(AG42+AH42*路线!B32+AI42)) -> 109 | AM40: =AJ40+AM39 -> 169 | AQ40: 4 | AS40: =IF(AQ40=-1,0,IF(AQ40<=3,词条!I7,词条!J7)) -> 13 | AT40: =IF(AQ40=-1,0,INT(AQ42+AR42*路线!B31+AS40*路线!B15+AS42)) -> 127 | AU40: =IF(AQ40=-1,0,INT(AQ42+AR42*路线!B31+AS40*路线!B18+AS42)) -> 114 | AV40: =IF(AQ40=-1,0,INT(AQ42+AR42*路线!B31+AS40*路线!B21+AS42)) -> 75 | BA40: 4 | BC40: =IF(BA40=-1,0,IF(BA40<=3,词条!I6,词条!J6)) -> 4 | BD40: =IF(BA40=-1,0,IF(路线!C6="计算",INT(BA42+BB42*路线!B31+BC40*路线!B14+BC42+20),INT(BA42+BB42*路线!B31+BC40*路线!B14+BC42))) -> 111 | BE40: =IF(BA40=-1,0,IF(路线!C6="计算",INT(BA42+BB42*路线!B31+BC40*路线!B17+BC42+20),INT(BA42+BB42*路线!B31+BC40*路线!B17+BC42))) -> 107 | BF40: =IF(BA40=-1,0,IF(路线!C6="计算",INT(BA42+BB42*路线!B31+BC40*路线!B20+BC42+20),INT(BA42+BB42*路线!B31+BC40*路线!B20+BC42))) -> 95
C41: 百分比 | D41: sp训练 | E41: 事件 | M41: 基础值 | N41: sp训练 | O41: 事件 | P41: SP | W41: 基础值 | X41: 训练 | Y41: 事件 | Z41: SP | AG41: 基础值 | AH41: 休息 | AI41: 事件 | AM41: =AK40+AM39 -> 169 | AQ41: 基础值 | AR41: 外出 | AS41: 事件 | AT41: SP | BA41: 基础值 | BB41: 外出 | BC41: 事件
C42: =IF(C40=-1,0,INDEX(词条!C4:G4,C40+1)) -> 8.5 | D42: =IF(C40=-1,0,IF(C40<=2,词条!C7,词条!D7)) -> 17 | E42: =IF(C40=-1,0,CHOOSE(C40+1,词条!C2,词条!D2,词条!D2,词条!D2,词条!E2)) -> 40 | F42: 通用 | M42: =IF(M40=-1,0,INDEX(词条!C3:G3,M40+1)) -> 60 | N42: =IF(M40=-1,0,IF(M40<=2,词条!C7,词条!D7)) -> 17 | O42: =IF(M40=-1,0,CHOOSE(M40+1,词条!C2,词条!D2,词条!D2,词条!D2,词条!E2)) -> 40 | P42: 理性 | W42: =IF(W40=-1,0,INDEX(词条!C3:G3,W40+1)) -> 60 | X42: =IF(W40=-1,0,IF(W40<=3,词条!F6,词条!G6)) -> 4 | Y42: =IF(W40=-1,0,CHOOSE(W40+1,词条!C2,词条!D2,词条!D2,词条!D2,词条!E2)) -> 40 | Z42: 通用 | AG42: =IF(AG40=-1,0,INDEX(词条!I3:M3,AG40+1)) -> 45 | AH42: =IF(AG40=-1,0,IF(AG40<=2,词条!I5,词条!J5)) -> 17 | AI42: =IF(AG40=-1,0,CHOOSE(AG40+1,词条!I2,词条!I2,词条!J2,词条!J2,词条!K2)) -> 30 | AJ42: 理性 | AM42: =AL40+AM39 -> 169 | AQ42: =IF(AQ40=-1,0,INDEX(词条!I3:M3,AQ40+1)) -> 45 | AR42: =IF(AQ40=-1,0,IF(AQ40<=2,词条!I17,词条!J17)) -> 10 | AS42: =IF(AQ40=-1,0,CHOOSE(AQ40+1,词条!I2,词条!I2,词条!J2,词条!J2,词条!K2)) -> 30 | AT42: 通用 | BA42: =IF(BA40=-1,0,INDEX(词条!I3:M3,BA40+1)) -> 45 | BB42: =IF(BA40=-1,0,IF(BA40<=2,词条!I17,词条!J17)) -> 10 | BC42: =IF(BA40=-1,0,CHOOSE(BA40+1,词条!I2,词条!I2,词条!J2,词条!J2,词条!K2)) -> 30 | BD42: 感性
A44: 一時休戦です（一时休战） | K44: 夏を満喫するわよ！（水枪） | U44: 「ア」じゃなくて「エ」！（黄补课） | AE44: 第五種接近遭遇（电风扇） | AM44: 道具属性 | AN44: 集中抓卡 | AO44: キュっと締めて（sr蓝购物） | AY44: りっぱなすすき！（麦穗）
C45: 破数 | E45: 支给 | F45: 第一属性 | G45: 第二属性 | H45: 第三属性 | M45: 破数 | N45: m强化 | O45: 营业 | P45: 第一属性 | Q45: 第二属性 | R45: 第三属性 | W45: 破数 | Y45: 抓m卡 | Z45: 第一属性 | AA45: 第二属性 | AB45: 第三属性 | AG45: 破数 | AI45: 训练 | AJ45: 第一属性 | AK45: 第二属性 | AL45: 第三属性 | AM45: =AN45*6 -> 60 | AN45: 10 | AQ45: 破数 | AS45: 训练 | AT45: 第一属性 | AU45: 第二属性 | AV45: 第三属性 | BA45: 破数 | BB45: 外出 | BC45: sp训练 | BD45: 第一属性 | BE45: 第二属性 | BF45: 第三属性
C46: 4 | E46: =IF(C46=-1,0,IF(C46<=3,词条!C12,词条!D12)) -> 17 | F46: =IF(C46=-1,0,IF(路线!C6="计算",INT((C48/100)*路线!B11+D48*路线!B15+E46*路线!B34+E48+20),INT((C48/100)*路线!B11+D48*路线!B15+E46*路线!B34+E48))) -> 255 | G46: =IF(C46=-1,0,IF(路线!C6="计算",INT((C48/100)*路线!B12+D48*路线!B18+E46*路线!B34+E48+20),INT((C48/100)*路线!B12+D48*路线!B18+E46*路线!B34+E48))) -> 219 | H46: =IF(C46=-1,0,IF(路线!C6="计算",INT((C48/100)*路线!B13+D48*路线!B21+E46*路线!B34+E48+20),INT((C48/100)*路线!B13+D48*路线!B21+E46*路线!B34+E48))) -> 132 | M46: 4 | N46: =IF(M46=-1,0,IF(M46<=1,词条!C10,词条!D11)) -> 9 | O46: =IF(M46=-1,0,IF(M46<=3,词条!C16,词条!D16)) -> 7 | P46: =IF(M46=-1,0,INT((M48/100)*路线!B11+N46*路线!B29+N48*路线!B15+O46*路线!B30+O48)) -> 251 | Q46: =IF(M46=-1,0,INT((M48/100)*路线!B12+N46*路线!B29+N48*路线!B18+O46*路线!B30+O48)) -> 215 | R46: =IF(M46=-1,0,INT((M48/100)*路线!B13+N46*路线!B29+N48*路线!B21+O46*路线!B30+O48)) -> 128 | W46: 4 | Y46: =IF(W46=-1,0,IF(W46<=3,词条!C13,词条!D13)) -> 3 | Z46: =IF(W46=-1,0,IF(路线!C6="计算",INT(W48+X48*路线!B14+Y46*路线!B24+Y48+20),INT(W48+X48*路线!B14+Y46*路线!B24+Y48))) -> 180 | AA46: =IF(W46=-1,0,IF(路线!C6="计算",INT(W48+X48*路线!B17+Y46*路线!B24+Y48+20),INT(W48+X48*路线!B17+Y46*路线!B24+Y48))) -> 174 | AB46: =IF(W46=-1,0,IF(路线!C6="计算",INT(W48+X48*路线!B20+Y46*路线!B24+Y48+20),INT(W48+X48*路线!B20+Y46*路线!B24+Y48))) -> 156 | AG46: 4 | AI46: =IF(AG46=-1,0,IF(AG46<=3,词条!I6,词条!J6)) -> 4 | AJ46: =IF(AG46=-1,0,INT((AG48/100)*路线!B11+AH48*路线!B33+AI46*路线!B14+AI48)) -> 135 | AK46: =IF(AG46=-1,0,INT((AG48/100)*路线!B12+AH48*路线!B33+AI46*路线!B17+AI48)) -> 117 | AL46: =IF(AG46=-1,0,INT((AG48/100)*路线!B13+AH48*路线!B33+AI46*路线!B20+AI48)) -> 78 | AM46: =AJ46+AM45 -> 195 | AQ46: 4 | AS46: =IF(AQ46=-1,0,IF(AQ46<=3,词条!I6,词条!J6)) -> 4 | AT46: =IF(AQ46=-1,0,INT(AQ48+AR48*路线!B39+AS46*路线!B14+AS48)) -> 107 | AU46: =IF(AQ46=-1,0,INT(AQ48+AR48*路线!B39+AS46*路线!B17+AS48)) -> 103 | AV46: =IF(AQ46=-1,0,INT(AQ48+AR48*路线!B39+AS46*路线!B20+AS48)) -> 91 | BA46: 4 | BB46: =IF(BA46=-1,0,IF(BA46=0,词条!I17,词条!J17)) -> 10 | BC46: =IF(BA46=-1,0,IF(BA46<=3,词条!I7,词条!J7)) -> 13 | BD46: =IF(BA46=-1,0,INT(BA48+BB46*路线!B31+BB48*路线!B34+BC46*路线!B15+BC48)) -> 160 | BE46: =IF(BA46=-1,0,INT(BA48+BB46*路线!B31+BB48*路线!B34+BC46*路线!B18+BC48)) -> 147 | BF46: =IF(BA46=-1,0,INT(BA48+BB46*路线!B31+BB48*路线!B34+BC46*路线!B21+BC48)) -> 108
C47: 百分比 | D47: sp训练 | E47: 事件 | M47: 百分比 | N47: sp训练 | O47: 事件 | W47: 基础值 | X47: 训练 | Y47: 事件 | Z47: SP | AG47: 百分比 | AH47: 相谈 | AI47: 事件 | AM47: =AK46+AM45 -> 177 | AQ47: 基础值 | AR47: 相谈饮料 | AS47: 事件 | BA47: 基础值 | BB47: 支给 | BC47: 事件
C48: =IF(C46=-1,0,INDEX(词条!C4:G4,C46+1)) -> 8.5 | D48: =IF(C46=-1,0,IF(C46<=2,词条!C7,词条!D7)) -> 17 | E48: =IF(C46=-1,0,CHOOSE(C46+1,词条!C2,词条!D2,词条!D2,词条!D2,词条!E2)) -> 40 | F48: 感性 | M48: =IF(M46=-1,0,INDEX(词条!C4:G4,M46+1)) -> 8.5 | N48: =IF(M46=-1,0,IF(M46<=2,词条!C7,词条!D7)) -> 17 | O48: =IF(M46=-1,0,CHOOSE(M46+1,词条!C2,词条!D2,词条!D2,词条!D2,词条!E2)) -> 40 | P48: 理性 | W48: =IF(W46=-1,0,INDEX(词条!C3:G3,W46+1)) -> 60 | X48: =IF(W46=-1,0,IF(W46<=2,词条!C6,词条!D6)) -> 6 | Y48: =IF(W46=-1,0,CHOOSE(W46+1,词条!C2,词条!D2,词条!D2,词条!D2,词条!E2)) -> 40 | Z48: 理性 | AG48: =IF(AG46=-1,0,INDEX(词条!I4:M4,AG46+1)) -> 6.4 | AH48: =IF(AG46=-1,0,IF(AG46<=2,词条!I18,词条!J18)) -> 8 | AI48: =IF(AG46=-1,0,CHOOSE(AG46+1,词条!I2,词条!I2,词条!J2,词条!J2,词条!K2)) -> 30 | AJ48: 感性 | AM48: =AL46+AM45 -> 138 | AQ48: =IF(AQ46=-1,0,INDEX(词条!I3:M3,AQ46+1)) -> 45 | AR48: =IF(AQ46=-1,0,IF(AQ46<=2,词条!I20,词条!J20)) -> 8 | AS48: =IF(AQ46=-1,0,CHOOSE(AQ46+1,词条!I2,词条!I2,词条!J2,词条!J2,词条!K2)) -> 30 | AT48: 感性 | BA48: =IF(BA46=-1,0,INDEX(词条!I3:M3,BA46+1)) -> 45 | BB48: =IF(BA46=-1,0,IF(BA46<=2,词条!I12,词条!J12)) -> 11 | BC48: =IF(BA46=-1,0,CHOOSE(BA46+1,词条!I2,词条!I2,词条!J2,词条!J2,词条!K2)) -> 30 | BD48: 理性
...

Sheet 路线
A1: 第一属性 | B1: 黄 | C1: 最低sp数 | E1: 3 / 3 | H1: 总属性 | I1: =I2+I3+I4+I5+I6+I7 -> 1500 | K1: 3 / 2 / 1 | N1: 总属性 | O1: =O2+O3+O4+O5+O6+O7 -> 1457 | T1: 总属性 | U1: =U2+U3+U4+U5+U6+U7 -> 1413 | W1: 2 / 2 / 2 | Z1: 总属性 | AA1: =AA2+AA3+AA4+AA5+AA6+AA7 -> 1360 | AC1: 2 / 4 | AF1: 总属性 | AG1: =AG2+AG3+AG4+AG5+AG6+AG7 -> 1446 | AI1: 路线模拟
A2: 第二属性 | B2: 蓝 | C2: 1 | E2: =借卡计算!E23 -> 【借】新たな挑戦の成功ですわ！（黄书签） | I2: =借卡计算!I23 -> 229 | K2: =借卡计算!K23 -> 【借】新たな挑戦の成功ですわ！（黄书签） | O2: =借卡计算!O23 -> 229 | Q2: =借卡计算!Q23 -> 【借】そろそろ焼けたかな？（红薯） | U2: =借卡计算!U23 -> 222 | W2: =借卡计算!W23 -> 【借】新たな挑戦の成功ですわ！（黄书签） | AA2: =借卡计算!AA23 -> 229 | AC2: =借卡计算!AC23 -> 【借】新たな挑戦の成功ですわ！（黄书签） | AG2: =借卡计算!AG23 -> 229 | AI2: 请输入初始基础值及百分比
A3: 流派 | B3: 理性 | C3: 1 | E3: =借卡计算!E24 -> 推し活なひととき、だね！（猫头鹰） | I3: =借卡计算!I24 -> 301 | K3: =借卡计算!K24 -> 推し活なひととき、だね！（猫头鹰） | O3: =借卡计算!O24 -> 301 | Q3: =借卡计算!Q24 -> 利用し合うのが友達！（黄毛摸鱼） | U3: =借卡计算!U24 -> 254 | W3: =借卡计算!W24 -> 推し活なひととき、だね！（猫头鹰） | AA3: =借卡计算!AA24 -> 301 | AC3: =借卡计算!AC24 -> 推し活なひととき、だね！（猫头鹰） | AG3: =借卡计算!AG24 -> 301 | AI3: 基础值 | AK3: 245 | AL3: 145 | AM3: 223
A4: 道具属性 | B4: 计算 | C4: 1 | E4: =借卡计算!E25 -> ぜったい追いついてやる！（红叶） | I4: =借卡计算!I25 -> 269 | K4: =借卡计算!K25 -> ぜったい追いついてやる！（红叶） | O4: =借卡计算!O25 -> 269 | Q4: =借卡计算!Q25 -> 千奈の恩返し（恩返） | U4: =借卡计算!U25 -> 225 | W4: =借卡计算!W25 -> そろそろ焼けたかな？（红薯） | AA4: =借卡计算!AA25 -> 222 | AC4: =借卡计算!AC25 -> そろそろ焼けたかな？（红薯） | AG4: =借卡计算!AG25 -> 222 | AI4: 百分比 | AK4: 31.2 | AL4: 7 | AM4: 38.6
A5: 审查类型 | B5: 均衡 | C5: （仅主属） | E5: =借卡计算!E26 -> そろそろ焼けたかな？（红薯） | I5: =借卡计算!I26 -> 222 | K5: =借卡计算!K26 -> そろそろ焼けたかな？（红薯） | O5: =借卡计算!O26 -> 222 | Q5: =借卡计算!Q26 -> 新たな挑戦の成功ですわ！（黄书签） | U5: =借卡计算!U26 -> 229 | W5: =借卡计算!W26 -> 利用し合うのが友達！（黄毛摸鱼） | AA5: =借卡计算!AA26 -> 254 | AC5: =借卡计算!AC26 -> 利用し合うのが友達！（黄毛摸鱼） | AG5: =借卡计算!AG26 -> 254 | AI5: 请输入支援卡部分词条总加成
A6: 塞卡等效属性(20/1) | C6: 计算 | E6: =借卡计算!E27 -> 利用し合うのが友達！（黄毛摸鱼） | I6: =借卡计算!I27 -> 254 | K6: =借卡计算!K27 -> 利用し合うのが友達！（黄毛摸鱼） | O6: =借卡计算!O27 -> 254 | Q6: =借卡计算!Q27 -> 推し活なひととき、だね！（猫头鹰） | U6: =借卡计算!U27 -> 301 | W6: =借卡计算!W27 -> 2名様、ご案内～♪（毛球偷吃） | AA6: =借卡计算!AA27 -> 182 | AC6: =借卡计算!AC27 -> 千奈の恩返し（恩返） | AG6: =借卡计算!AG27 -> 225 | AI6: 训练（sp与普通之和） | AK6: 47 | AL6: 0 | AM6: 47
E7: =借卡计算!E28 -> 千奈の恩返し（恩返） | I7: =借卡计算!I28 -> 225 | K7: =借卡计算!K28 -> 2名様、ご案内～♪（毛球偷吃） | O7: =借卡计算!O28 -> 182 | Q7: =借卡计算!Q28 -> 2名様、ご案内～♪（毛球偷吃） | U7: =借卡计算!U28 -> 182 | W7: =借卡计算!W28 -> 屈辱の2位（马给马给） | AA7: =借卡计算!AA28 -> 172 | AC7: =借卡计算!AC28 -> 夏を満喫するわよ！（水枪） | AG7: =借卡计算!AG28 -> 215 | AI7: 营业 | AK7: 0 | AL7: 0 | AM7: 7
AI8: 挑战道具加成比例 | AK8: 40
D9: NIA | I9: NIA master | Q9: =IF(B1=B2,"请输入不同的第一第二属性","") | AI9: 1周SP | AJ9: 100 | AK9: 1 | AL9: 0 | AM9: 0
B10: 路线选择 | D10: NIA通常 | E10: NIA强化 | F10: NIA购物 | G10: 自定义 | I10: mas支给 | J10: mas外出 | K10: mas购物 | L10: mas买卡 | M10: mas删卡 | N10: mas外出强化 | AI10: 2周营业 | AJ10: 80 | AK10: 0 | AL10: 1 | AM10: 0
A11: 一属性值 | B11: =IF($B$5="单极",850,900) -> 900 | D11: 850 | E11: 850 | F11: 850 | G11: 850 | I11: =IF($B$5="单极",850,900) -> 900 | J11: =IF($B$5="单极",850,900) -> 900 | K11: =IF($B$5="单极",850,900) -> 900 | L11: =IF($B$5="单极",850,900) -> 900 | M11: =IF($B$5="单极",850,900) -> 900 | N11: =IF($B$5="单极",850,900) -> 900 | AI11: 4周SP | AJ11: 100 | AK11: 1 | AL11: 0 | AM11: 0
A12: 二属性值 | B12: =IF($B$5="单极",800,680) -> 680 | D12: 850 | E12: 850 | F12: 850 | G12: 850 | I12: =IF($B$5="单极",800,680) -> 680 | J12: =IF($B$5="单极",800,680) -> 680 | K12: =IF($B$5="单极",800,680) -> 680 | L12: =IF($B$5="单极",800,680) -> 680 | M12: =IF($B$5="单极",800,680) -> 680 | N12: =IF($B$5="单极",800,680) -> 680 | AI12: 5周营业 | AJ12: 80 | AK12: 0 | AL12: 1 | AM12: 0
A13: 三属性值 | B13: =IF($B$5="单极",190,250) -> 250 | D13: 250 | E13: 250 | F13: 250 | G13: 250 | I13: =IF($B$5="单极",190,250) -> 250 | J13: =IF($B$5="单极",190,250) -> 250 | K13: =IF($B$5="单极",190,250) -> 250 | L13: =IF($B$5="单极",190,250) -> 250 | M13: =IF($B$5="单极",190,250) -> 250 | N13: =IF($B$5="单极",190,250) -> 250 | AI13: 7周营业 | AJ13: 80 | AK13: 0 | AL13: 1 | AM13: 0
A14: 一属训练 | B14: =IF($B$5="单极",3,4) -> 4 | D14: 4 | E14: 4 | F14: 4 | G14: 4 | I14: =IF($B$5="单极",3,4) -> 4 | J14: =IF($B$5="单极",3,4) -> 4 | K14: =IF($B$5="单极",3,4) -> 4 | L14: =IF($B$5="单极",3,4) -> 4 | M14: =IF($B$5="单极",3,4) -> 4 | N14: =IF($B$5="单极",3,4) -> 4 | AD14: 试镜属性根据所选的第一、第二属性和审查类型计算→ | AI14: 一镜基础属性 | AK14: =ROUNDUP(IF(B5="均衡",IF(B1="红",IF(AK15<=1116,0.04766*AK15,IF(AK15>=4124,92,0.0129*AK15+38.8)),IF(B2="红",IF(AK15<=530,0.08314*AK15,IF(AK15>=1917,76,0.023*AK15+31.9)),IF(AK15<=323,0.11232*AK15,IF(AK15>=1107,62,0.0328*AK15+25.7)))),IF(B1="红",IF(AK15<=1577,0.04553*AK15,IF(AK15>=4103,116,0.0175*AK15+44.2)),IF(B2="红",IF(AK15<=542,0.07405*AK15,IF(AK15>=1914,69,0.021*AK15+28.8)),IF(AK15<=618,0.05239*AK15,IF(AK15>=1066,46,0.0304*AK15+13.6))))),0) -> 62 | AL14: =ROUNDUP(IF(B5="均衡",IF(B1="蓝",IF(AL15<=1116,0.04766*AL15,IF(AL15>=4124,92,0.0129*AL15+38.8)),IF(B2="蓝",IF(AL15<=530,0.08314*AL15,IF(AL15>=1917,76,0.023*AL15+31.9)),IF(AL15<=323,0.11232*AL15,IF(AL15>=1107,62,0.0328*AL15+25.7)))),IF(B1="蓝",IF(AL15<=1577,0.04553*AL15,IF(AL15>=4103,116,0.0175*AL15+44.2)),IF(B2="蓝",IF(AL15<=542,0.07405*AL15,IF(AL15>=1914,69,0.021*AL15+28.8)),IF(AL15<=618,0.05239*AL15,IF(AL15>=1066,46,0.0304*AL15+13.6))))),0) -> 76 | AM14: =ROUNDUP(IF(B5="均衡",IF(B1="黄",IF(AM15<=1116,0.04766*AM15,IF(AM15>=4124,92,0.0129*AM15+38.8)),IF(B2="黄",IF(AM15<=530,0.08314*AM15,IF(AM15>=1917,76,0.023*AM15+31.9)),IF(AM15<=323,0.11232*AM15,IF(AM15>=1107,62,0.0328*AM15+25.7)))),IF(B1="黄",IF(AM15<=1577,0.04553*AM15,IF(AM15>=4103,116,0.0175*AM15+44.2)),IF(B2="黄",IF(AM15<=542,0.07405*AM15,IF(AM15>=1914,69,0.021*AM15+28.8)),IF(AM15<=618,0.05239*AM15,IF(AM15>=1066,46,0.0304*AM15+13.6))))),0) -> 86
A15: 一属sp | B15: =IF($B$5="单极",3,4) -> 4 | D15: 4 | E15: 4 | F15: 4 | G15: 4 | I15: =IF($B$5="单极",3,4) -> 4 | J15: =IF($B$5="单极",3,4) -> 4 | K15: =IF($B$5="单极",3,4) -> 4 | L15: =IF($B$5="单极",3,4) -> 4 | M15: =IF($B$5="单极",3,4) -> 4 | N15: =IF($B$5="单极",3,4) -> 4 | AI15: 打分 | AK15: 3689 | AL15: 2823 | AM15: 3626
A16: 一属通常 | B16: 0 | D16: 0 | E16: 0 | F16: 0 | G16: 0 | I16: 0 | J16: 0 | K16: 0 | L16: 0 | M16: 0 | N16: 0 | AI16: 结算属性 | AK16: =AK14+INT(AK14*AK4/100)+INT(AK14*AK8/100) -> 105 | AL16: =AL14+INT(AL14*AL4/100)+INT(AL14*AK8/100) -> 111 | AM16: =AM14+INT(AM14*AM4/100)+INT(AM14*AK8/100) -> 153
A17: 二属训练 | B17: =IF($B$5="单极",4,3) -> 3 | D17: 4 | E17: 4 | F17: 4 | G17: 4 | I17: =IF($B$5="单极",4,3) -> 3 | J17: =IF($B$5="单极",4,3) -> 3 | K17: =IF($B$5="单极",4,3) -> 3 | L17: =IF($B$5="单极",4,3) -> 3 | M17: =IF($B$5="单极",4,3) -> 3 | N17: =IF($B$5="单极",4,3) -> 3 | AI17: 11周SP | AJ17: 120 | AK17: 0 | AL17: 0 | AM17: 1
A18: 二属sp | B18: =IF($B$5="单极",4,3) -> 3 | D18: 4 | E18: 4 | F18: 4 | G18: 4 | I18: =IF($B$5="单极",4,3) -> 3 | J18: =IF($B$5="单极",4,3) -> 3 | K18: =IF($B$5="单极",4,3) -> 3 | L18: =IF($B$5="单极",4,3) -> 3 | M18: =IF($B$5="单极",4,3) -> 3 | N18: =IF($B$5="单极",4,3) -> 3 | AI18: 12周营业 | AJ18: 110 | AK18: 0 | AL18: 1 | AM18: 0
A19: 二属通常 | B19: 0 | D19: 0 | E19: 0 | F19: 0 | G19: 0 | I19: 0 | J19: 0 | K19: 0 | L19: 0 | M19: 0 | N19: 0 | AI19: 14周SP | AJ19: 120 | AK19: 0 | AL19: 0 | AM19: 1
A20: 三属训练 | B20: 0 | D20: 0 | E20: 0 | F20: 0 | G20: 0 | I20: 0 | J20: 0 | K20: 0 | L20: 0 | M20: 0 | N20: 0 | AI20: 15周营业 | AJ20: 110 | AK20: 0 | AL20: 1 | AM20: 0
A21: 三属sp | B21: 0 | D21: 0 | E21: 0 | F21: 0 | G21: 0 | I21: 0 | J21: 0 | K21: 0 | L21: 0 | M21: 0 | N21: 0 | AI21: 二镜基础属性 | AK21: =ROUNDUP(IF(B5="均衡",IF(B1="红",IF(AK22<=13245,0.005247*AK22,IF(AK22>=46026,119,0.00151*AK22+49.5)),IF(B2="红",IF(AK22<=6292,0.009123*AK22,IF(AK22>=21498,98,0.00267*AK22+40.6)),IF(AK22<=4060,0.01182*AK22,IF(AK22>=12183,80,0.00394*AK22+32)))),IF(B1="红",IF(AK22<=11521,0.007386*AK22,IF(AK22>=46250,149,0.00184*AK22+63.9)),IF(B2="红",IF(AK22<=4806,0.0104226*AK22,IF(AK22>=21502,89,0.00233*AK22+38.9)),IF(AK22<=3093,0.010926*AK22,IF(AK22>=12158,59,0.00278*AK22+25.2))))),0) -> 80 | AL21: =ROUNDUP(IF(B5="均衡",IF(B1="蓝",IF(AL22<=13245,0.005247*AL22,IF(AL22>=46026,119,0.00151*AL22+49.5)),IF(B2="蓝",IF(AL22<=6292,0.009123*AL22,IF(AL22>=21498,98,0.00267*AL22+40.6)),IF(AL22<=4060,0.01182*AL22,IF(AL22>=12183,80,0.00394*AL22+32)))),IF(B1="蓝",IF(AL22<=11521,0.007386*AL22,IF(AL22>=46250,149,0.00184*AL22+63.9)),IF(B2="蓝",IF(AL22<=4806,0.0104226*AL22,IF(AL22>=21502,89,0.00233*AL22+38.9)),IF(AL22<=3093,0.010926*AL22,IF(AL22>=12158,59,0.00278*AL22+25.2))))),0) -> 89 | AM21: =ROUNDUP(IF(B5="均衡",IF(B1="黄",IF(AM22<=13245,0.005247*AM22,IF(AM22>=46026,119,0.00151*AM22+49.5)),IF(B2="黄",IF(AM22<=6292,0.009123*AM22,IF(AM22>=21498,98,0.00267*AM22+40.6)),IF(AM22<=4060,0.01182*AM22,IF(AM22>=12183,80,0.00394*AM22+32)))),IF(B1="黄",IF(AM22<=11521,0.007386*AM22,IF(AM22>=46250,149,0.00184*AM22+63.9)),IF(B2="黄",IF(AM22<=4806,0.0104226*AM22,IF(AM22>=21502,89,0.00233*AM22+38.9)),IF(AM22<=3093,0.010926*AM22,IF(AM22>=12158,59,0.00278*AM22+25.2))))),0) -> 119
A22: 三属通常 | B22: 0 | D22: 0 | E22: 0 | F22: 0 | G22: 0 | I22: 0 | J22: 0 | K22: 0 | L22: 0 | M22: 0 | N22: 0 | AI22: 打分 | AK22: 17701 | AL22: 18077 | AM22: 85615
A23: 抓a卡 | B23: 10 | D23: 4 | E23: 4 | F23: 4 | G23: 4 | I23: 8 | J23: 6 | K23: 8 | L23: 15 | M23: 10 | N23: 6 | AI23: 结算属性 | AK23: =AK21+INT(AK21*AK4/100)+INT(AK21*AK8/100) -> 136 | AL23: =AL21+INT(AL21*AL4/100)+INT(AL21*AK8/100) -> 130 | AM23: =AM21+INT(AM21*AM4/100)+INT(AM21*AK8/100) -> 211
A24: 抓m卡 | B24: 12 | D24: 8 | E24: 8 | F24: 8 | G24: 8 | I24: 16 | J24: 14 | K24: 16 | L24: 15 | M24: 12 | N24: 14 | AI24: 19周SP | AJ24: 150 | AK24: 0 | AL24: 0 | AM24: 1
A25: 抓好调卡 | B25: 12 | D25: 5 | E25: 5 | F25: 5 | G25: 5 | I25: 12 | J25: 10 | K25: 12 | L25: 14 | M25: 12 | N25: 10 | AI25: 20周营业 | AJ25: 130 | AK25: 0 | AL25: 1 | AM25: 0
A26: 抓温存卡 | B26: 17 | D26: 7 | E26: 7 | F26: 7 | G26: 7 | I26: 17 | J26: 15 | K26: 17 | L26: 19 | M26: 17 | N26: 15 | AI26: 22周SP | AJ26: 150 | AK26: 1 | AL26: 0 | AM26: 0
A27: 抓好印象卡 | B27: 17 | D27: 9 | E27: 9 | F27: 9 | G27: 9 | I27: 17 | J27: 15 | K27: 17 | L27: 19 | M27: 17 | N27: 15 | AI27: 23周营业 | AJ27: 130 | AK27: 0 | AL27: 1 | AM27: 0
A28: a强化 | B28: 2 | D28: 1 | E28: 1 | F28: 1 | G28: 1 | I28: 2 | J28: 2 | K28: 2 | L28: 2 | M28: 2 | N28: 2 | AI28: 24周SP | AJ28: 150 | AK28: 1 | AL28: 0 | AM28: 0
A29: m强化 | B29: 2 | D29: 3 | E29: 8 | F29: 2 | G29: 3 | I29: 2 | J29: 5 | K29: 2 | L29: 2 | M29: 2 | N29: 14 | AI29: 三镜基础属性 | AK29: =ROUNDUP(IF(B5="均衡",IF(B1="红",IF(AK30<=35048,0.0028132*AK30,IF(AK30>=137135,172,0.000719*AK30+73.4)),IF(B2="红",IF(AK30<=14400,0.0055556*AK30,IF(AK30>=64000,142,0.00125*AK30+62)),IF(AK30<=10000,0.00672*AK30,IF(AK30>=36522,116,0.00184*AK30+48.8)))),IF(B1="红",IF(AK30<=38997,0.0032156*AK30,IF(AK30>=136601,215,0.000918*AK30+89.6)),IF(B2="红",IF(AK30<=18135,0.0041465*AK30,IF(AK30>=63729,129,0.00118*AK30+53.8)),IF(AK30<=9927,0.0050166*AK30,IF(AK30>=36350,86,0.00137*AK30+36.2))))),0) -> 116 | AL29: =ROUNDUP(IF(B5="均衡",IF(B1="蓝",IF(AL30<=35048,0.0028132*AL30,IF(AL30>=137135,172,0.000719*AL30+73.4)),IF(B2="蓝",IF(AL30<=14400,0.0055556*AL30,IF(AL30>=64000,142,0.00125*AL30+62)),IF(AL30<=10000,0.00672*AL30,IF(AL30>=36522,116,0.00184*AL30+48.8)))),IF(B1="蓝",IF(AL30<=38997,0.0032156*AL30,IF(AL30>=136601,215,0.000918*AL30+89.6)),IF(B2="蓝",IF(AL30<=18135,0.0041465*AL30,IF(AL30>=63729,129,0.00118*AL30+53.8)),IF(AL30<=9927,0.0050166*AL30,IF(AL30>=36350,86,0.00137*AL30+36.2))))),0) -> 118 | AM29: =ROUNDUP(IF(B5="均衡",IF(B1="黄",IF(AM30<=35048,0.0028132*AM30,IF(AM30>=137135,172,0.000719*AM30+73.4)),IF(B2="黄",IF(AM30<=14400,0.0055556*AM30,IF(AM30>=64000,142,0.00125*AM30+62)),IF(AM30<=10000,0.00672*AM30,IF(AM30>=36522,116,0.00184*AM30+48.8)))),IF(B1="黄",IF(AM30<=38997,0.0032156*AM30,IF(AM30>=136601,215,0.000918*AM30+89.6)),IF(B2="黄",IF(AM30<=18135,0.0041465*AM30,IF(AM30>=63729,129,0.00118*AM30+53.8)),IF(AM30<=9927,0.0050166*AM30,IF(AM30>=36350,86,0.00137*AM30+36.2))))),0) -> 172
A30: 营业 | B30: 7 | D30: 7 | E30: 7 | F30: 7 | G30: 7 | I30: 7 | J30: 7 | K30: 7 | L30: 7 | M30: 7 | N30: 7 | AI30: 打分 | AK30: 73823 | AL30: 44056 | AM30: 297035
A31: 外出 | B31: 0 | D31: 5 | E31: 5 | F31: 2 | G31: 5 | I31: 1 | J31: 5 | K31: 1 | L31: 0 | M31: 0 | N31: 5 | AI31: 结算属性 | AK31: =AK29+INT(AK29*AK4/100)+INT(AK29*AK8/100) -> 198 | AL31: =AL29+INT(AL29*AL4/100)+INT(AL29*AK8/100) -> 173 | AM31: =AM29+INT(AM29*AM4/100)+INT(AM29*AK8/100) -> 306
A32: 休息 | B32: 2 | D32: 0 | E32: 0 | F32: 0 | G32: 0 | I32: 0 | J32: 0 | K32: 0 | L32: 2 | M32: 2 | N32: 0 | AG32: 总和 | AH32: =AK32+AL32+AM32 -> 4849 | AI32: 最终属性 | AK32: =AK3+AK16+AK23+AK31+INT(IF(AK9=1,AJ9*(1+AK4/100)+AK6,0))+INT(IF(AK11=1,AJ11*(1+AK4/100)+AK6,0))+INT(IF(AK17=1,AJ17*(1+AK4/100)+AK6,0))+INT(IF(AK19=1,AJ19*(1+AK4/100)+AK6,0))+INT(IF(AK24=1,AJ24*(1+AK4/100)+AK6,0))+INT(IF(AK26=1,AJ26*(1+AK4/100)+AK6,0))+INT(IF(AK28=1,AJ28*(1+AK4/100)+AK6,0))+IF(AK10=1,AJ10,0)+IF(AK12=1,AJ12,0)+IF(AK13=1,AJ13,0)+IF(AK18=1,AJ18,0)+IF(AK20=1,AJ20,0)+IF(AK25=1,AJ25,0)+IF(AK27=1,AJ27,0)+AK7*B30+AK34*B23+AK35*B24+AK36*B28+AK37*B29+AK38*B31+AK39*B32+AK40*B33+AK41*B34+AK42*B36+AK43*B37+AK44*B38+AK45*B39+AK46*B40+AK47*B25+AK48*B26+AK49*B27+AK50+AK51+AK52+AK53*B41 -> 1692 | AL32: =AL3+AL16+AL23+AL31+INT(IF(AL9=1,AJ9*(1+AL4/100)+AL6,0))+INT(IF(AL11=1,AJ11*(1+AL4/100)+AL6,0))+INT(IF(AL17=1,AJ17*(1+AL4/100)+AL6,0))+INT(IF(AL19=1,AJ19*(1+AL4/100)+AL6,0))+INT(IF(AL24=1,AJ24*(1+AL4/100)+AL6,0))+INT(IF(AL26=1,AJ26*(1+AL4/100)+AL6,0))+INT(IF(AL28=1,AJ28*(1+AL4/100)+AL6,0))+IF(AL10=1,AJ10,0)+IF(AL12=1,AJ12,0)+IF(AL13=1,AJ13,0)+IF(AL18=1,AJ18,0)+IF(AL20=1,AJ20,0)+IF(AL25=1,AJ25,0)+IF(AL27=1,AJ27,0)+AL7*B30+AL34*B23+AL35*B24+AL36*B28+AL37*B29+AL38*B31+AL39*B32+AL40*B33+AL41*B34+AL42*B36+AL43*B37+AL44*B38+AL45*B39+AL46*B40+AL47*B25+AL48*B26+AL49*B27+AL50+AL51+AL52+AL53*B41 -> 1279 | AM32: =AM3+AM16+AM23+AM31+INT(IF(AM9=1,AJ9*(1+AM4/100)+AM6,0))+INT(IF(AM11=1,AJ11*(1+AM4/100)+AM6,0))+INT(IF(AM17=1,AJ17*(1+AM4/100)+AM6,0))+INT(IF(AM19=1,AJ19*(1+AM4/100)+AM6,0))+INT(IF(AM24=1,AJ24*(1+AM4/100)+AM6,0))+INT(IF(AM26=1,AJ26*(1+AM4/100)+AM6,0))+INT(IF(AM28=1,AJ28*(1+AM4/100)+AM6,0))+IF(AM10=1,AJ10,0)+IF(AM12=1,AJ12,0)+IF(AM13=1,AJ13,0)+IF(AM18=1,AJ18,0)+IF(AM20=1,AJ20,0)+IF(AM25=1,AJ25,0)+IF(AM27=1,AJ27,0)+AM7*B30+AM34*B23+AM35*B24+AM36*B28+AM37*B29+AM38*B31+AM39*B32+AM40*B33+AM41*B34+AM42*B36+AM43*B37+AM44*B38+AM45*B39+AM46*B40+AM47*B25+AM48*B26+AM49*B27+AM50+AM51+AM52+AM53*B41 -> 1878
A33: 相谈 | B33: 4 | D33: 1 | E33: 1 | F33: 3 | G33: 1 | I33: 3 | J33: 1 | K33: 3 | L33: 3 | M33: 4 | N33: 1 | AI33: 其余支援卡词条加成
A34: 支给 | B34: 3 | D34: 0 | E34: 0 | F34: 0 | G34: 0 | I34: 3 | J34: 0 | K34: 3 | L34: 4 | M34: 3 | N34: 0 | AG34: 包括抓任意卡 | AI34: 抓a卡 | AK34: 3 | AL34: 0 | AM34: 0
A35: 删卡 | B35: 10 | D35: 3 | E35: 3 | F35: 3 | G35: 3 | I35: 8 | J35: 6 | K35: 6 | L35: 6 | M35: 10 | N35: 6 | AI35: 抓m卡 | AK35: 0 | AL35: 0 | AM35: 0
A36: 删m卡 | B36: 3 | D36: 3 | E36: 3 | F36: 3 | G36: 3 | I36: 3 | J36: 3 | K36: 3 | L36: 3 | M36: 3 | N36: 3 | AG36: 包括任意强化 | AI36: a强化 | AK36: 0 | AL36: 0 | AM36: 8
A37: 删a卡 | B37: 3 | D37: 3 | E37: 3 | F37: 3 | G37: 3 | I37: 3 | J37: 3 | K37: 3 | L37: 3 | M37: 3 | N37: 3 | AI37: m强化 | AK37: 7 | AL37: 0 | AM37: 8
A38: 变卡 | B38: 3 | D38: 3 | E38: 3 | F38: 3 | G38: 3 | I38: 3 | J38: 3 | K38: 3 | L38: 3 | M38: 3 | N38: 3 | AI38: 外出 | AK38: 0 | AL38: 0 | AM38: 0
A39: 相谈饮料 | B39: 2 | D39: 2 | E39: 0 | F39: 11 | G39: 2 | I39: 2 | J39: 0 | K39: 12 | L39: 2 | M39: 2 | N39: 0 | AI39: 休息 | AK39: 0 | AL39: 0 | AM39: 0
A40: 饮料 | B40: 14 | D40: 6 | E40: 4 | F40: 14 | G40: 6 | I40: 14 | J40: 10 | K40: 16 | L40: 10 | M40: 14 | N40: 10 | AI40: 相谈 | AK40: 0 | AL40: 0 | AM40: 0
...

Sheet 词条
A1: =IF(AQ4=-1,0,INDEX(I3,AQ4+1)) -> 33 | B1: SSR | H1: SR
A2: 事件 | C2: 30 | D2: 35 | E2: 40 | I2: 22 | J2: 26 | K2: 30
A3: 基础值 | C3: 48 | D3: 51 | E3: 54 | F3: 57 | G3: 60 | I3: 33 | J3: 36 | K3: 39 | L3: 42 | M3: 45
A4: 百分比 | C4: 6.5 | D4: 7 | E4: 7.5 | F4: 8 | G4: 8.5 | I4: 4.4 | J4: 4.9 | K4: 5.4 | L4: 5.9 | M4: 6.4
A5: 休息 | C5: 17 | D5: 22 | I5: 9 | J5: 17
A6: 训练 | C6: 4 | D6: 6 | F6: 3 | G6: 4 | I6: 2 | J6: 4
A7: sp训练 | C7: 13 | D7: 17 | F7: 9 | G7: 13 | I7: 7 | J7: 13
A8: 通常训练 | I8: 7 | J8: 13
A9: 强化 | C9: 3 | D9: 4 | I9: 2 | J9: 3
A10: m强化 | C10: 7 | D10: 9 | F10: 5 | G10: 7 | I10: 4 | J10: 6
A11: a强化 | C11: 7 | D11: 9 | F11: 5 | G11: 7
A12: 支给 | C12: 12 | D12: 17 | I12: 6 | J12: 11
A13: 抓m卡 | C13: 2 | D13: 3 | F13: 1 | G13: 2
A14: 抓a卡 | C14: 2 | D14: 3 | F14: 1 | G14: 2
A15: 抓卡 | I15: 1 | J15: 2
A16: 营业 | C16: 5 | D16: 7 | F16: 4 | G16: 5 | I16: 3 | J16: 5
A17: 外出 | C17: 11 | D17: 15 | I17: 5 | J17: 10
A18: 相谈 | C18: 8 | D18: 11 | F18: 6 | G18: 8 | I18: 4 | J18: 8
A19: 试验终了 | C19: 17 | D19: 22 | F19: 11 | G19: 17 | I19: 9 | J19: 17
A20: 饮料 | C20: 8 | D20: 11 | F20: 4 | G20: 5 | I20: 4 | J20: 8
A21: 抓好调卡 | C21: 3 | D21: 4
A22: 删卡 | C22: 8 | D22: 11 | E22: 次限 | F22: 17 | G22: 22 | I22: 4 | J22: 8 | K22: 次限 | L22: 8 | M22: 16
A23: 抓温存卡 | C23: 3 | D23: 4
A24: 抓好印象卡 | C24: 3 | D24: 4 | I24: 2 | J24: 3
A25: 变卡 | C25: 16 | D25: 21
A26: 指导 | C26: 8 | D26: 11

Sheet 第一属性比较
D1: 属性值 | E1: 流派 | F1: sp | G1: 属性 | H1: 污染 | I1: 带出道具或S卡 | J1: 满破属性 | L1: 红感性 | M1: 红理性 | N1: 红非凡 | O1: 蓝感性 | P1: 蓝理性 | Q1: 蓝非凡 | R1: 黄感性 | S1: 黄理性 | T1: 黄非凡 | U1: 红感性sp | V1: 蓝感性sp | W1: 黄感性sp | X1: 红理性sp | Y1: 蓝理性sp | Z1: 黄理性sp | AA1: 红非凡sp | AB1: 蓝非凡sp | AC1: 黄非凡sp | AD1: 红借卡感性非sp | AE1: 蓝借卡感性非sp | AF1: 黄借卡感性非sp | AG1: 红借卡感性sp | AH1: 蓝借卡感性sp | AI1: 黄借卡感性sp | AJ1: 红借卡理性非sp | AK1: 蓝借卡理性非sp | AL1: 黄借卡理性非sp | AM1: 红借卡理性sp | AN1: 蓝借卡理性sp | AO1: 黄借卡理性sp | AP1: 红借卡非凡非sp | AQ1: 蓝借卡非凡非sp | AR1: 黄借卡非凡非sp | AS1: 红借卡非凡sp | AT1: 蓝借卡非凡sp | AU1: 黄借卡非凡sp
A2: 相変わらず不器用ね（幼驯染） | D2: =持有情况!F100-ROW()*0.00001 -> 235.99998 | E2: 2 | F2: 0 | G2: 1 | H2: 0 | J2: =INT(60+4*路线!B27+17*路线!B15+15*路线!B31+40)-ROW()*0.00001 -> 235.99998 | L2: =IF(AND(OR(E2=1,E2=0),G2=1),D2,"") | M2: =IF(AND(OR(E2=2,E2=0),G2=1),D2,"") -> 235.99998 | N2: =IF(AND(OR(E2=3,E2=0),G2=1),D2,"") | O2: =IF(AND(OR(E2=1,E2=0),G2=2),D2,"") | P2: =IF(AND(OR(E2=2,E2=0),G2=2),D2,"") | Q2: =IF(AND(OR(E2=3,E2=0),G2=2),D2,"") | R2: =IF(AND(OR(E2=1,E2=0),G2=3),D2,"") | S2: =IF(AND(OR(E2=2,E2=0),G2=3),D2,"") | T2: =IF(AND(OR(E2=3,E2=0),G2=3),D2,"") | U2: =IF(AND(OR(E2=1,E2=0),G2=1,F2=1),D2,"") | V2: =IF(AND(OR(E2=1,E2=0),G2=2,F2=1),D2,"") | W2: =IF(AND(OR(E2=1,E2=0),G2=3,F2=1),D2,"") | X2: =IF(AND(OR(E2=2,E2=0),G2=1,F2=1),D2,"") | Y2: =IF(AND(OR(E2=2,E2=0),G2=2,F2=1),D2,"") | Z2: =IF(AND(OR(E2=2,E2=0),G2=3,F2=1),D2,"") | AA2: =IF(AND(OR(E2=3,E2=0),G2=1,F2=1),D2,"") | AB2: =IF(AND(OR(E2=3,E2=0),G2=2,F2=1),D2,"") | AC2: =IF(AND(OR(E2=3,E2=0),G2=3,F2=1),D2,"") | AD2: =IF(AND(OR(E2=1,E2=0),G2=1,F2=0),J2,"") | AE2: =IF(AND(OR(E2=1,E2=0),G2=2,F2=0),J2,"") | AF2: =IF(AND(OR(E2=1,E2=0),G2=3,F2=0),J2,"") | AG2: =IF(AND(OR(E2=1,E2=0),G2=1,F2=1),J2,"") | AH2: =IF(AND(OR(E2=1,E2=0),G2=2,F2=1),J2,"") | AI2: =IF(AND(OR(E2=1,E2=0),G2=3,F2=1),J2,"") | AJ2: =IF(AND(OR(E2=2,E2=0),G2=1,F2=0),J2,"") -> 235.99998 | AK2: =IF(AND(OR(E2=2,E2=0),G2=2,F2=0),J2,"") | AL2: =IF(AND(OR(E2=2,E2=0),G2=3,F2=0),J2,"") | AM2: =IF(AND(OR(E2=2,E2=0),G2=1,F2=1),J2,"") | AN2: =IF(AND(OR(E2=2,E2=0),G2=2,F2=1),J2,"") | AO2: =IF(AND(OR(E2=2,E2=0),G2=3,F2=1),J2,"") | AP2: =IF(AND(OR(E2=3,E2=0),G2=1,F2=0),J2,"") | AQ2: =IF(AND(OR(E2=3,E2=0),G2=2,F2=0),J2,"") | AR2: =IF(AND(OR(E2=3,E2=0),G2=3,F2=0),J2,"") | AS2: =IF(AND(OR(E2=3,E2=0),G2=1,F2=1),J2,"") | AT2: =IF(AND(OR(E2=3,E2=0),G2=2,F2=1),J2,"") | AU2: =IF(AND(OR(E2=3,E2=0),G2=3,F2=1),J2,"")
A3: 夏を満喫するわよ！（水枪） | D3: =持有情况!P46-ROW()*0.00001 -> 250.99997 | E3: 2 | F3: 0 | G3: 2 | H3: 1 | I3: 水枪 | J3: =INT((8.5/100)*路线!B11+9*路线!B29+17*路线!B15+7*路线!B30+40)-ROW()*0.00001 -> 250.99997 | L3: =IF(AND(OR(E3=1,E3=0),G3=1),D3,"") | M3: =IF(AND(OR(E3=2,E3=0),G3=1),D3,"") | N3: =IF(AND(OR(E3=3,E3=0),G3=1),D3,"") | O3: =IF(AND(OR(E3=1,E3=0),G3=2),D3,"") | P3: =IF(AND(OR(E3=2,E3=0),G3=2),D3,"") -> 250.99997 | Q3: =IF(AND(OR(E3=3,E3=0),G3=2),D3,"") | R3: =IF(AND(OR(E3=1,E3=0),G3=3),D3,"") | S3: =IF(AND(OR(E3=2,E3=0),G3=3),D3,"") | T3: =IF(AND(OR(E3=3,E3=0),G3=3),D3,"") | U3: =IF(AND(OR(E3=1,E3=0),G3=1,F3=1),D3,"") | V3: =IF(AND(OR(E3=1,E3=0),G3=2,F3=1),D3,"") | W3: =IF(AND(OR(E3=1,E3=0),G3=3,F3=1),D3,"") | X3: =IF(AND(OR(E3=2,E3=0),G3=1,F3=1),D3,"") | Y3: =IF(AND(OR(E3=2,E3=0),G3=2,F3=1),D3,"") | Z3: =IF(AND(OR(E3=2,E3=0),G3=3,F3=1),D3,"") | AA3: =IF(AND(OR(E3=3,E3=0),G3=1,F3=1),D3,"") | AB3: =IF(AND(OR(E3=3,E3=0),G3=2,F3=1),D3,"") | AC3: =IF(AND(OR(E3=3,E3=0),G3=3,F3=1),D3,"") | AD3: =IF(AND(OR(E3=1,E3=0),G3=1,F3=0),J3,"") | AE3: =IF(AND(OR(E3=1,E3=0),G3=2,F3=0),J3,"") | AF3: =IF(AND(OR(E3=1,E3=0),G3=3,F3=0),J3,"") | AG3: =IF(AND(OR(E3=1,E3=0),G3=1,F3=1),J3,"") | AH3: =IF(AND(OR(E3=1,E3=0),G3=2,F3=1),J3,"") | AI3: =IF(AND(OR(E3=1,E3=0),G3=3,F3=1),J3,"") | AJ3: =IF(AND(OR(E3=2,E3=0),G3=1,F3=0),J3,"") | AK3: =IF(AND(OR(E3=2,E3=0),G3=2,F3=0),J3,"") -> 250.99997 | AL3: =IF(AND(OR(E3=2,E3=0),G3=3,F3=0),J3,"") | AM3: =IF(AND(OR(E3=2,E3=0),G3=1,F3=1),J3,"") | AN3: =IF(AND(OR(E3=2,E3=0),G3=2,F3=1),J3,"") | AO3: =IF(AND(OR(E3=2,E3=0),G3=3,F3=1),J3,"") | AP3: =IF(AND(OR(E3=3,E3=0),G3=1,F3=0),J3,"") | AQ3: =IF(AND(OR(E3=3,E3=0),G3=2,F3=0),J3,"") | AR3: =IF(AND(OR(E3=3,E3=0),G3=3,F3=0),J3,"") | AS3: =IF(AND(OR(E3=3,E3=0),G3=1,F3=1),J3,"") | AT3: =IF(AND(OR(E3=3,E3=0),G3=2,F3=1),J3,"") | AU3: =IF(AND(OR(E3=3,E3=0),G3=3,F3=1),J3,"")
A4: ここから始まるんだね！（相册） | D4: =持有情况!P106-ROW()*0.00001 -> 342.99996 | E4: 1 | F4: 0 | G4: 2 | H4: 1 | I4: 相册 | J4: =INT((8.5/100)*路线!B11+11*路线!B35+17*路线!B15+7*路线!B30+40)-ROW()*0.00001 -> 342.99996 | L4: =IF(AND(OR(E4=1,E4=0),G4=1),D4,"") | M4: =IF(AND(OR(E4=2,E4=0),G4=1),D4,"") | N4: =IF(AND(OR(E4=3,E4=0),G4=1),D4,"") | O4: =IF(AND(OR(E4=1,E4=0),G4=2),D4,"") -> 342.99996 | P4: =IF(AND(OR(E4=2,E4=0),G4=2),D4,"") | Q4: =IF(AND(OR(E4=3,E4=0),G4=2),D4,"") | R4: =IF(AND(OR(E4=1,E4=0),G4=3),D4,"") | S4: =IF(AND(OR(E4=2,E4=0),G4=3),D4,"") | T4: =IF(AND(OR(E4=3,E4=0),G4=3),D4,"") | U4: =IF(AND(OR(E4=1,E4=0),G4=1,F4=1),D4,"") | V4: =IF(AND(OR(E4=1,E4=0),G4=2,F4=1),D4,"") | W4: =IF(AND(OR(E4=1,E4=0),G4=3,F4=1),D4,"") | X4: =IF(AND(OR(E4=2,E4=0),G4=1,F4=1),D4,"") | Y4: =IF(AND(OR(E4=2,E4=0),G4=2,F4=1),D4,"") | Z4: =IF(AND(OR(E4=2,E4=0),G4=3,F4=1),D4,"") | AA4: =IF(AND(OR(E4=3,E4=0),G4=1,F4=1),D4,"") | AB4: =IF(AND(OR(E4=3,E4=0),G4=2,F4=1),D4,"") | AC4: =IF(AND(OR(E4=3,E4=0),G4=3,F4=1),D4,"") | AD4: =IF(AND(OR(E4=1,E4=0),G4=1,F4=0),J4,"") | AE4: =IF(AND(OR(E4=1,E4=0),G4=2,F4=0),J4,"") -> 342.99996 | AF4: =IF(AND(OR(E4=1,E4=0),G4=3,F4=0),J4,"") | AG4: =IF(AND(OR(E4=1,E4=0),G4=1,F4=1),J4,"") | AH4: =IF(AND(OR(E4=1,E4=0),G4=2,F4=1),J4,"") | AI4: =IF(AND(OR(E4=1,E4=0),G4=3,F4=1),J4,"") | AJ4: =IF(AND(OR(E4=2,E4=0),G4=1,F4=0),J4,"") | AK4: =IF(AND(OR(E4=2,E4=0),G4=2,F4=0),J4,"") | AL4: =IF(AND(OR(E4=2,E4=0),G4=3,F4=0),J4,"") | AM4: =IF(AND(OR(E4=2,E4=0),G4=1,F4=1),J4,"") | AN4: =IF(AND(OR(E4=2,E4=0),G4=2,F4=1),J4,"") | AO4: =IF(AND(OR(E4=2,E4=0),G4=3,F4=1),J4,"") | AP4: =IF(AND(OR(E4=3,E4=0),G4=1,F4=0),J4,"") | AQ4: =IF(AND(OR(E4=3,E4=0),G4=2,F4=0),J4,"") | AR4: =IF(AND(OR(E4=3,E4=0),G4=3,F4=0),J4,"") | AS4: =IF(AND(OR(E4=3,E4=0),G4=1,F4=1),J4,"") | AT4: =IF(AND(OR(E4=3,E4=0),G4=2,F4=1),J4,"") | AU4: =IF(AND(OR(E4=3,E4=0),G4=3,F4=1),J4,"")
A5: 似合うんじゃない？（气球） | D5: =持有情况!P58-ROW()*0.00001 -> 183.99995 | E5: 2 | F5: 0 | G5: 2 | H5: 1 | I5: 气球 | J5: =INT((8.5/100)*路线!B11+17*路线!B15+15*路线!B31+40)-ROW()*0.00001 -> 183.99995 | L5: =IF(AND(OR(E5=1,E5=0),G5=1),D5,"") | M5: =IF(AND(OR(E5=2,E5=0),G5=1),D5,"") | N5: =IF(AND(OR(E5=3,E5=0),G5=1),D5,"") | O5: =IF(AND(OR(E5=1,E5=0),G5=2),D5,"") | P5: =IF(AND(OR(E5=2,E5=0),G5=2),D5,"") -> 183.99995 | Q5: =IF(AND(OR(E5=3,E5=0),G5=2),D5,"") | R5: =IF(AND(OR(E5=1,E5=0),G5=3),D5,"") | S5: =IF(AND(OR(E5=2,E5=0),G5=3),D5,"") | T5: =IF(AND(OR(E5=3,E5=0),G5=3),D5,"") | U5: =IF(AND(OR(E5=1,E5=0),G5=1,F5=1),D5,"") | V5: =IF(AND(OR(E5=1,E5=0),G5=2,F5=1),D5,"") | W5: =IF(AND(OR(E5=1,E5=0),G5=3,F5=1),D5,"") | X5: =IF(AND(OR(E5=2,E5=0),G5=1,F5=1),D5,"") | Y5: =IF(AND(OR(E5=2,E5=0),G5=2,F5=1),D5,"") | Z5: =IF(AND(OR(E5=2,E5=0),G5=3,F5=1),D5,"") | AA5: =IF(AND(OR(E5=3,E5=0),G5=1,F5=1),D5,"") | AB5: =IF(AND(OR(E5=3,E5=0),G5=2,F5=1),D5,"") | AC5: =IF(AND(OR(E5=3,E5=0),G5=3,F5=1),D5,"") | AD5: =IF(AND(OR(E5=1,E5=0),G5=1,F5=0),J5,"") | AE5: =IF(AND(OR(E5=1,E5=0),G5=2,F5=0),J5,"") | AF5: =IF(AND(OR(E5=1,E5=0),G5=3,F5=0),J5,"") | AG5: =IF(AND(OR(E5=1,E5=0),G5=1,F5=1),J5,"") | AH5: =IF(AND(OR(E5=1,E5=0),G5=2,F5=1),J5,"") | AI5: =IF(AND(OR(E5=1,E5=0),G5=3,F5=1),J5,"") | AJ5: =IF(AND(OR(E5=2,E5=0),G5=1,F5=0),J5,"") | AK5: =IF(AND(OR(E5=2,E5=0),G5=2,F5=0),J5,"") -> 183.99995 | AL5: =IF(AND(OR(E5=2,E5=0),G5=3,F5=0),J5,"") | AM5: =IF(AND(OR(E5=2,E5=0),G5=1,F5=1),J5,"") | AN5: =IF(AND(OR(E5=2,E5=0),G5=2,F5=1),J5,"") | AO5: =IF(AND(OR(E5=2,E5=0),G5=3,F5=1),J5,"") | AP5: =IF(AND(OR(E5=3,E5=0),G5=1,F5=0),J5,"") | AQ5: =IF(AND(OR(E5=3,E5=0),G5=2,F5=0),J5,"") | AR5: =IF(AND(OR(E5=3,E5=0),G5=3,F5=0),J5,"") | AS5: =IF(AND(OR(E5=3,E5=0),G5=1,F5=1),J5,"") | AT5: =IF(AND(OR(E5=3,E5=0),G5=2,F5=1),J5,"") | AU5: =IF(AND(OR(E5=3,E5=0),G5=3,F5=1),J5,"")
A6: 利用し合うのが友達！（黄毛摸鱼） | D6: =IF(路线!B4="计算",持有情况!S112,持有情况!P112)-ROW()*0.00001 -> 253.99994 | E6: 0 | F6: 0 | G6: 2 | H6: 1 | J6: =IF(路线!B4="计算",INT(60+22+21*IF(路线!B38<=3,路线!B38,3)+7*路线!B30+40+20),INT(60+22+21*IF(路线!B38<=3,路线!B38,3)+7*路线!B30+40))-ROW()*0.00001 -> 253.99994 | L6: =IF(AND(OR(E6=1,E6=0),G6=1),D6,"") | M6: =IF(AND(OR(E6=2,E6=0),G6=1),D6,"") | N6: =IF(AND(OR(E6=3,E6=0),G6=1),D6,"") | O6: =IF(AND(OR(E6=1,E6=0),G6=2),D6,"") -> 253.99994 | P6: =IF(AND(OR(E6=2,E6=0),G6=2),D6,"") -> 253.99994 | Q6: =IF(AND(OR(E6=3,E6=0),G6=2),D6,"") -> 253.99994 | R6: =IF(AND(OR(E6=1,E6=0),G6=3),D6,"") | S6: =IF(AND(OR(E6=2,E6=0),G6=3),D6,"") | T6: =IF(AND(OR(E6=3,E6=0),G6=3),D6,"") | U6: =IF(AND(OR(E6=1,E6=0),G6=1,F6=1),D6,"") | V6: =IF(AND(OR(E6=1,E6=0),G6=2,F6=1),D6,"") | W6: =IF(AND(OR(E6=1,E6=0),G6=3,F6=1),D6,"") | X6: =IF(AND(OR(E6=2,E6=0),G6=1,F6=1),D6,"") | Y6: =IF(AND(OR(E6=2,E6=0),G6=2,F6=1),D6,"") | Z6: =IF(AND(OR(E6=2,E6=0),G6=3,F6=1),D6,"") | AA6: =IF(AND(OR(E6=3,E6=0),G6=1,F6=1),D6,"") | AB6: =IF(AND(OR(E6=3,E6=0),G6=2,F6=1),D6,"") | AC6: =IF(AND(OR(E6=3,E6=0),G6=3,F6=1),D6,"") | AD6: =IF(AND(OR(E6=1,E6=0),G6=1,F6=0),J6,"") | AE6: =IF(AND(OR(E6=1,E6=0),G6=2,F6=0),J6,"") -> 253.99994 | AF6: =IF(AND(OR(E6=1,E6=0),G6=3,F6=0),J6,"") | AG6: =IF(AND(OR(E6=1,E6=0),G6=1,F6=1),J6,"") | AH6: =IF(AND(OR(E6=1,E6=0),G6=2,F6=1),J6,"") | AI6: =IF(AND(OR(E6=1,E6=0),G6=3,F6=1),J6,"") | AJ6: =IF(AND(OR(E6=2,E6=0),G6=1,F6=0),J6,"") | AK6: =IF(AND(OR(E6=2,E6=0),G6=2,F6=0),J6,"") -> 253.99994 | AL6: =IF(AND(OR(E6=2,E6=0),G6=3,F6=0),J6,"") | AM6: =IF(AND(OR(E6=2,E6=0),G6=1,F6=1),J6,"") | AN6: =IF(AND(OR(E6=2,E6=0),G6=2,F6=1),J6,"") | AO6: =IF(AND(OR(E6=2,E6=0),G6=3,F6=1),J6,"") | AP6: =IF(AND(OR(E6=3,E6=0),G6=1,F6=0),J6,"") | AQ6: =IF(AND(OR(E6=3,E6=0),G6=2,F6=0),J6,"") -> 253.99994 | AR6: =IF(AND(OR(E6=3,E6=0),G6=3,F6=0),J6,"") | AS6: =IF(AND(OR(E6=3,E6=0),G6=1,F6=1),J6,"") | AT6: =IF(AND(OR(E6=3,E6=0),G6=2,F6=1),J6,"") | AU6: =IF(AND(OR(E6=3,E6=0),G6=3,F6=1),J6,"")
